2025-07-25 10:19:06.840 WARNING (ImportExecutor_0) [py.warnings] /usr/local/lib/python3.13/site-packages/google/__init__.py:2: UserWarning: pkg_resources is deprecated as an API. See https://setuptools.pypa.io/en/latest/pkg_resources.html. The pkg_resources package is slated for removal as early as 2025-11-30. Refrain from using this package or pin to Setuptools<81.
  __import__('pkg_resources').declare_namespace(__name__)

2025-07-25 10:19:15.489 ERROR (MainThread) [homeassistant.components.automation] Automation with alias 'Outdoor Lights On at Sunset' failed to setup actions and has been disabled: Unknown device 'cfb8cff49b4fc7c05f007793e10e2808'
2025-07-25 13:52:08.762 ERROR (MainThread) [homeassistant.components.roborock.coordinator] Error fetching roborock data: Failed to update data
2025-07-25 18:45:39.962 ERROR (MainThread) [homeassistant.components.roborock.coordinator] Error fetching roborock data: Failed to update data
2025-07-25 18:52:53.283 ERROR (MainThread) [homeassistant.components.roborock.coordinator] Error fetching roborock data: Failed to update data
2025-07-25 18:58:01.762 ERROR (MainThread) [homeassistant.components.roborock.coordinator] Error fetching roborock data: Failed to update data
2025-07-25 18:58:08.815 WARNING (MainThread) [roborock.version_1_apis.roborock_local_client_v1] [Q5 Max+] [Errno 104] Connection reset by peer
2025-07-25 19:27:18.762 ERROR (MainThread) [homeassistant.components.roborock.coordinator] Error fetching roborock data: Failed to update data
2025-07-25 19:43:18.765 ERROR (MainThread) [homeassistant.components.roborock.coordinator] Error fetching roborock data: Failed to update data
2025-07-25 19:43:36.701 WARNING (MainThread) [roborock.version_1_apis.roborock_local_client_v1] [Q5 Max+] [Errno 104] Connection reset by peer
2025-07-25 19:44:53.762 ERROR (MainThread) [homeassistant.components.roborock.coordinator] Error fetching roborock data: Failed to update data
2025-07-25 19:44:59.320 WARNING (MainThread) [roborock.version_1_apis.roborock_local_client_v1] [Q5 Max+] [Errno 104] Connection reset by peer
2025-07-25 19:58:08.763 ERROR (MainThread) [homeassistant.components.roborock.coordinator] Error fetching roborock data: Failed to update data
2025-07-25 19:58:24.340 WARNING (MainThread) [roborock.version_1_apis.roborock_local_client_v1] [Q5 Max+] [Errno 104] Connection reset by peer
2025-07-25 19:59:14.762 ERROR (MainThread) [homeassistant.components.roborock.coordinator] Error fetching roborock data: Failed to update data
2025-07-25 19:59:21.941 WARNING (MainThread) [roborock.version_1_apis.roborock_local_client_v1] [Q5 Max+] [Errno 104] Connection reset by peer
2025-07-25 20:00:22.760 ERROR (MainThread) [homeassistant.components.roborock.coordinator] Error fetching roborock data: Failed to update data
2025-07-25 20:00:30.023 WARNING (MainThread) [roborock.version_1_apis.roborock_local_client_v1] [Q5 Max+] [Errno 104] Connection reset by peer
2025-07-25 20:01:28.761 ERROR (MainThread) [homeassistant.components.roborock.coordinator] Error fetching roborock data: Failed to update data
2025-07-25 20:01:35.175 WARNING (MainThread) [roborock.version_1_apis.roborock_local_client_v1] [Q5 Max+] [Errno 104] Connection reset by peer
2025-07-25 20:03:10.961 ERROR (MainThread) [homeassistant.components.roborock.coordinator] Error fetching roborock data: Failed to update data
2025-07-25 20:10:54.762 ERROR (MainThread) [homeassistant.components.roborock.coordinator] Error fetching roborock data: Failed to update data
2025-07-25 20:11:05.092 WARNING (MainThread) [roborock.version_1_apis.roborock_local_client_v1] [Q5 Max+] [Errno 104] Connection reset by peer
2025-07-25 20:30:01.413 WARNING (MainThread) [roborock.version_1_apis.roborock_local_client_v1] [Q5 Max+] [Errno 104] Connection reset by peer
2025-07-25 21:19:23.368 WARNING (MainThread) [roborock.version_1_apis.roborock_local_client_v1] [Q5 Max+] [Errno 104] Connection reset by peer
2025-07-25 21:19:24.764 ERROR (MainThread) [homeassistant.components.roborock.coordinator] Error fetching roborock data: Failed to update data
2025-07-25 21:36:43.762 ERROR (MainThread) [homeassistant.components.roborock.coordinator] Error fetching roborock data: Failed to update data
2025-07-25 21:36:53.851 WARNING (MainThread) [roborock.version_1_apis.roborock_local_client_v1] [Q5 Max+] [Errno 104] Connection reset by peer
2025-07-25 22:44:07.763 ERROR (MainThread) [homeassistant.components.roborock.coordinator] Error fetching roborock data: Failed to update data
2025-07-26 03:08:45.698 ERROR (MainThread) [homeassistant.components.roborock.coordinator] Error fetching roborock data: Failed to update data
2025-07-26 07:30:11.934 WARNING (MainThread) [homeassistant.components.websocket_api.http.connection] [547038246560] from 192.168.8.154 (Mozilla/5.0 (Linux; Android 16; Pixel 7 Pro Build/BP2A.250705.008; wv) AppleWebKit/537.36 (KHTML, like Gecko) Version/4.0 Chrome/138.0.7204.158 Mobile Safari/537.36 Home Assistant/2025.7.1-16758 (Android 16; Pixel 7 Pro)): Disconnected: Did not receive auth message within 10 seconds
2025-07-26 07:30:18.194 WARNING (MainThread) [homeassistant.components.websocket_api.http.connection] [546945215488] from 192.168.8.154 (Mozilla/5.0 (Linux; Android 16; Pixel 7 Pro Build/BP2A.250705.008; wv) AppleWebKit/537.36 (KHTML, like Gecko) Version/4.0 Chrome/138.0.7204.158 Mobile Safari/537.36 Home Assistant/2025.7.1-16758 (Android 16; Pixel 7 Pro)): Disconnected: Received close message during auth phase
2025-07-26 17:51:51.836 WARNING (MainThread) [roborock.version_1_apis.roborock_mqtt_client_v1] [Q5 Max+] Attempting to create a future with an existing id 1 (0)... New id is 13835. Code may not function properly.
2025-07-26 17:51:51.841 ERROR (MainThread) [homeassistant] Error doing job: Exception in callback RoborockFuture._set_result() (None)
Traceback (most recent call last):
  File "/usr/local/lib/python3.13/asyncio/events.py", line 89, in _run
    self._context.run(self._callback, *self._args)
    ~~~~~~~~~~~~~~~~~^^^^^^^^^^^^^^^^^^^^^^^^^^^^^
  File "/usr/local/lib/python3.13/site-packages/roborock/roborock_future.py", line 19, in _set_result
    self.fut.set_result(item)
    ~~~~~~~~~~~~~~~~~~~^^^^^^
asyncio.exceptions.InvalidStateError: invalid state
2025-07-26 19:42:08.834 WARNING (MainThread) [roborock.version_1_apis.roborock_mqtt_client_v1] [Q5 Max+] Attempting to create a future with an existing id 1 (0)... New id is 16413. Code may not function properly.
2025-07-26 19:42:08.839 ERROR (MainThread) [homeassistant] Error doing job: Exception in callback RoborockFuture._set_result() (None)
Traceback (most recent call last):
  File "/usr/local/lib/python3.13/asyncio/events.py", line 89, in _run
    self._context.run(self._callback, *self._args)
    ~~~~~~~~~~~~~~~~~^^^^^^^^^^^^^^^^^^^^^^^^^^^^^
  File "/usr/local/lib/python3.13/site-packages/roborock/roborock_future.py", line 19, in _set_result
    self.fut.set_result(item)
    ~~~~~~~~~~~~~~~~~~~^^^^^^
asyncio.exceptions.InvalidStateError: invalid state
2025-07-26 20:21:07.762 ERROR (MainThread) [homeassistant.components.roborock.coordinator] Error fetching roborock data: Failed to update data
2025-07-26 20:21:20.441 WARNING (MainThread) [roborock.version_1_apis.roborock_local_client_v1] [Q5 Max+] [Errno 104] Connection reset by peer
2025-07-26 20:24:56.873 WARNING (MainThread) [roborock.version_1_apis.roborock_local_client_v1] [Q5 Max+] [Errno 104] Connection reset by peer
2025-07-26 20:28:45.779 ERROR (MainThread) [homeassistant.components.roborock.coordinator] Error fetching roborock data: Failed to update data
2025-07-26 20:29:35.075 WARNING (MainThread) [roborock.version_1_apis.roborock_local_client_v1] [Q5 Max+] [Errno 104] Connection reset by peer
2025-07-26 20:31:14.920 WARNING (MainThread) [roborock.version_1_apis.roborock_local_client_v1] [Q5 Max+] [Errno 104] Connection reset by peer
2025-07-26 20:34:17.762 ERROR (MainThread) [homeassistant.components.roborock.coordinator] Error fetching roborock data: Failed to update data
2025-07-26 20:35:52.885 WARNING (MainThread) [roborock.version_1_apis.roborock_local_client_v1] [Q5 Max+] [Errno 104] Connection reset by peer
2025-07-26 20:37:02.762 ERROR (MainThread) [homeassistant.components.roborock.coordinator] Error fetching roborock data: Failed to update data
2025-07-26 20:37:20.189 WARNING (MainThread) [roborock.version_1_apis.roborock_local_client_v1] [Q5 Max+] [Errno 104] Connection reset by peer
2025-07-26 20:39:51.403 WARNING (MainThread) [homeassistant.helpers.service] Referenced entities light.plug_in_lamp_dimming_module_8 are missing or not currently available
2025-07-26 20:39:51.404 WARNING (MainThread) [homeassistant.helpers.service] Referenced entities switch.plant_lights are missing or not currently available
2025-07-26 20:40:56.017 WARNING (MainThread) [roborock.version_1_apis.roborock_local_client_v1] [Q5 Max+] [Errno 104] Connection reset by peer
2025-07-26 20:42:07.761 ERROR (MainThread) [homeassistant.components.roborock.coordinator] Error fetching roborock data: Failed to update data
2025-07-26 21:01:51.762 ERROR (MainThread) [homeassistant.components.roborock.coordinator] Error fetching roborock data: Failed to update data
2025-07-26 21:02:42.620 WARNING (MainThread) [roborock.version_1_apis.roborock_local_client_v1] [Q5 Max+] [Errno 104] Connection reset by peer
2025-07-26 21:03:31.761 ERROR (MainThread) [homeassistant.components.roborock.coordinator] Error fetching roborock data: Failed to update data
2025-07-26 21:08:10.302 WARNING (MainThread) [roborock.version_1_apis.roborock_local_client_v1] [Q5 Max+] [Errno 104] Connection reset by peer
2025-07-27 03:00:30.835 WARNING (MainThread) [roborock.version_1_apis.roborock_mqtt_client_v1] [Q5 Max+] Attempting to create a future with an existing id 1 (0)... New id is 22491. Code may not function properly.
2025-07-27 03:00:30.841 ERROR (MainThread) [homeassistant] Error doing job: Exception in callback RoborockFuture._set_result() (None)
Traceback (most recent call last):
  File "/usr/local/lib/python3.13/asyncio/events.py", line 89, in _run
    self._context.run(self._callback, *self._args)
    ~~~~~~~~~~~~~~~~~^^^^^^^^^^^^^^^^^^^^^^^^^^^^^
  File "/usr/local/lib/python3.13/site-packages/roborock/roborock_future.py", line 19, in _set_result
    self.fut.set_result(item)
    ~~~~~~~~~~~~~~~~~~~^^^^^^
asyncio.exceptions.InvalidStateError: invalid state
2025-07-27 07:30:12.857 WARNING (MainThread) [homeassistant.components.websocket_api.http.connection] [546973073632] from 192.168.8.154 (Mozilla/5.0 (Linux; Android 16; Pixel 7 Pro Build/BP2A.250705.008; wv) AppleWebKit/537.36 (KHTML, like Gecko) Version/4.0 Chrome/138.0.7204.158 Mobile Safari/537.36 Home Assistant/2025.7.1-16758 (Android 16; Pixel 7 Pro)): Disconnected: Did not receive auth message within 10 seconds
2025-07-27 07:30:27.090 WARNING (MainThread) [homeassistant.components.websocket_api.http.connection] [546957246144] from 192.168.8.154 (Mozilla/5.0 (Linux; Android 16; Pixel 7 Pro Build/BP2A.250705.008; wv) AppleWebKit/537.36 (KHTML, like Gecko) Version/4.0 Chrome/138.0.7204.158 Mobile Safari/537.36 Home Assistant/2025.7.1-16758 (Android 16; Pixel 7 Pro)): Disconnected: Did not receive auth message within 10 seconds
2025-07-27 07:30:30.273 WARNING (MainThread) [homeassistant.components.websocket_api.http.connection] [546972807904] from 192.168.8.154 (Mozilla/5.0 (Linux; Android 16; Pixel 7 Pro Build/BP2A.250705.008; wv) AppleWebKit/537.36 (KHTML, like Gecko) Version/4.0 Chrome/138.0.7204.158 Mobile Safari/537.36 Home Assistant/2025.7.1-16758 (Android 16; Pixel 7 Pro)): Disconnected: Received close message during auth phase
2025-07-27 07:39:17.488 WARNING (MainThread) [roborock.version_1_apis.roborock_local_client_v1] [Q5 Max+] [Errno 104] Connection reset by peer
2025-07-27 08:27:35.761 ERROR (MainThread) [homeassistant.components.roborock.coordinator] Error fetching roborock data: Failed to update data
2025-07-27 08:34:02.815 WARNING (MainThread) [roborock.version_1_apis.roborock_local_client_v1] [Q5 Max+] [Errno 104] Connection reset by peer
2025-07-27 09:03:20.762 ERROR (MainThread) [homeassistant.components.roborock.coordinator] Error fetching roborock data: Failed to update data
2025-07-27 09:06:13.042 WARNING (MainThread) [roborock.version_1_apis.roborock_local_client_v1] [Q5 Max+] [Errno 104] Connection reset by peer
2025-07-27 09:06:56.064 ERROR (MainThread) [homeassistant] Error doing job: Exception in callback RoborockFuture._set_result() (None)
Traceback (most recent call last):
  File "/usr/local/lib/python3.13/asyncio/events.py", line 89, in _run
    self._context.run(self._callback, *self._args)
    ~~~~~~~~~~~~~~~~~^^^^^^^^^^^^^^^^^^^^^^^^^^^^^
  File "/usr/local/lib/python3.13/site-packages/roborock/roborock_future.py", line 19, in _set_result
    self.fut.set_result(item)
    ~~~~~~~~~~~~~~~~~~~^^^^^^
asyncio.exceptions.InvalidStateError: invalid state
2025-07-27 09:07:59.196 ERROR (MainThread) [homeassistant.components.roborock.coordinator] Error fetching roborock data: Failed to update data
2025-07-27 09:12:13.761 ERROR (MainThread) [homeassistant.components.roborock.coordinator] Error fetching roborock data: Failed to update data
2025-07-27 09:13:13.654 WARNING (MainThread) [roborock.version_1_apis.roborock_local_client_v1] [Q5 Max+] [Errno 104] Connection reset by peer
2025-07-27 09:25:32.265 ERROR (MainThread) [homeassistant.components.roborock.coordinator] Error fetching roborock data: Failed to update data
2025-07-27 09:27:16.675 ERROR (MainThread) [homeassistant.components.roborock.coordinator] Error fetching roborock data: Failed to update data
2025-07-27 09:28:57.764 ERROR (MainThread) [homeassistant.components.roborock.coordinator] Error fetching roborock data: Failed to update data
2025-07-27 09:34:23.359 WARNING (MainThread) [roborock.version_1_apis.roborock_local_client_v1] [Q5 Max+] [Errno 104] Connection reset by peer
2025-07-27 09:37:00.762 ERROR (MainThread) [homeassistant.components.roborock.coordinator] Error fetching roborock data: Failed to update data
2025-07-27 09:41:23.551 WARNING (MainThread) [roborock.version_1_apis.roborock_local_client_v1] [Q5 Max+] [Errno 104] Connection reset by peer
2025-07-27 09:41:46.886 WARNING (MainThread) [roborock.version_1_apis.roborock_local_client_v1] [Q5 Max+] Attempting to create a future with an existing id 2 (3)... New id is 28376. Code may not function properly.
2025-07-27 09:42:01.891 WARNING (MainThread) [roborock.version_1_apis.roborock_local_client_v1] [Q5 Max+] Attempting to create a future with an existing id 2 (3)... New id is 28381. Code may not function properly.
2025-07-27 09:42:16.896 WARNING (MainThread) [roborock.version_1_apis.roborock_local_client_v1] [Q5 Max+] Attempting to create a future with an existing id 2 (3)... New id is 28387. Code may not function properly.
2025-07-27 09:42:31.902 WARNING (MainThread) [roborock.version_1_apis.roborock_local_client_v1] [Q5 Max+] Attempting to create a future with an existing id 2 (3)... New id is 28389. Code may not function properly.
2025-07-27 09:42:44.762 ERROR (MainThread) [homeassistant.components.roborock.coordinator] Error fetching roborock data: Failed to update data
2025-07-27 09:42:57.660 WARNING (MainThread) [roborock.version_1_apis.roborock_local_client_v1] [Q5 Max+] Attempting to create a future with an existing id 2 (3)... New id is 28393. Code may not function properly.
2025-07-27 09:43:12.666 WARNING (MainThread) [roborock.version_1_apis.roborock_local_client_v1] [Q5 Max+] Attempting to create a future with an existing id 2 (3)... New id is 28398. Code may not function properly.
2025-07-27 09:43:27.672 WARNING (MainThread) [roborock.version_1_apis.roborock_local_client_v1] [Q5 Max+] Attempting to create a future with an existing id 2 (3)... New id is 28402. Code may not function properly.
2025-07-27 09:43:42.678 WARNING (MainThread) [roborock.version_1_apis.roborock_local_client_v1] [Q5 Max+] Attempting to create a future with an existing id 2 (3)... New id is 28403. Code may not function properly.
2025-07-27 09:43:57.684 WARNING (MainThread) [roborock.version_1_apis.roborock_local_client_v1] [Q5 Max+] Attempting to create a future with an existing id 2 (3)... New id is 28407. Code may not function properly.
2025-07-27 09:44:12.689 WARNING (MainThread) [roborock.version_1_apis.roborock_local_client_v1] [Q5 Max+] Attempting to create a future with an existing id 2 (3)... New id is 28411. Code may not function properly.
2025-07-27 09:44:30.170 ERROR (MainThread) [homeassistant] Error doing job: Exception in callback RoborockFuture._set_result() (None)
Traceback (most recent call last):
  File "/usr/local/lib/python3.13/asyncio/events.py", line 89, in _run
    self._context.run(self._callback, *self._args)
    ~~~~~~~~~~~~~~~~~^^^^^^^^^^^^^^^^^^^^^^^^^^^^^
  File "/usr/local/lib/python3.13/site-packages/roborock/roborock_future.py", line 19, in _set_result
    self.fut.set_result(item)
    ~~~~~~~~~~~~~~~~~~~^^^^^^
asyncio.exceptions.InvalidStateError: invalid state
2025-07-27 09:44:30.173 ERROR (MainThread) [homeassistant] Error doing job: Exception in callback RoborockFuture._set_result() (None)
Traceback (most recent call last):
  File "/usr/local/lib/python3.13/asyncio/events.py", line 89, in _run
    self._context.run(self._callback, *self._args)
    ~~~~~~~~~~~~~~~~~^^^^^^^^^^^^^^^^^^^^^^^^^^^^^
  File "/usr/local/lib/python3.13/site-packages/roborock/roborock_future.py", line 19, in _set_result
    self.fut.set_result(item)
    ~~~~~~~~~~~~~~~~~~~^^^^^^
asyncio.exceptions.InvalidStateError: invalid state
2025-07-27 09:44:30.178 ERROR (MainThread) [homeassistant] Error doing job: Exception in callback RoborockFuture._set_result() (None)
Traceback (most recent call last):
  File "/usr/local/lib/python3.13/asyncio/events.py", line 89, in _run
    self._context.run(self._callback, *self._args)
    ~~~~~~~~~~~~~~~~~^^^^^^^^^^^^^^^^^^^^^^^^^^^^^
  File "/usr/local/lib/python3.13/site-packages/roborock/roborock_future.py", line 19, in _set_result
    self.fut.set_result(item)
    ~~~~~~~~~~~~~~~~~~~^^^^^^
asyncio.exceptions.InvalidStateError: invalid state
2025-07-27 09:44:30.193 ERROR (MainThread) [homeassistant] Error doing job: Exception in callback RoborockFuture._set_result() (None)
Traceback (most recent call last):
  File "/usr/local/lib/python3.13/asyncio/events.py", line 89, in _run
    self._context.run(self._callback, *self._args)
    ~~~~~~~~~~~~~~~~~^^^^^^^^^^^^^^^^^^^^^^^^^^^^^
  File "/usr/local/lib/python3.13/site-packages/roborock/roborock_future.py", line 19, in _set_result
    self.fut.set_result(item)
    ~~~~~~~~~~~~~~~~~~~^^^^^^
asyncio.exceptions.InvalidStateError: invalid state
2025-07-27 09:44:30.198 ERROR (MainThread) [homeassistant] Error doing job: Exception in callback RoborockFuture._set_result() (None)
Traceback (most recent call last):
  File "/usr/local/lib/python3.13/asyncio/events.py", line 89, in _run
    self._context.run(self._callback, *self._args)
    ~~~~~~~~~~~~~~~~~^^^^^^^^^^^^^^^^^^^^^^^^^^^^^
  File "/usr/local/lib/python3.13/site-packages/roborock/roborock_future.py", line 19, in _set_result
    self.fut.set_result(item)
    ~~~~~~~~~~~~~~~~~~~^^^^^^
asyncio.exceptions.InvalidStateError: invalid state
2025-07-27 09:44:30.203 ERROR (MainThread) [homeassistant] Error doing job: Exception in callback RoborockFuture._set_result() (None)
Traceback (most recent call last):
  File "/usr/local/lib/python3.13/asyncio/events.py", line 89, in _run
    self._context.run(self._callback, *self._args)
    ~~~~~~~~~~~~~~~~~^^^^^^^^^^^^^^^^^^^^^^^^^^^^^
  File "/usr/local/lib/python3.13/site-packages/roborock/roborock_future.py", line 19, in _set_result
    self.fut.set_result(item)
    ~~~~~~~~~~~~~~~~~~~^^^^^^
asyncio.exceptions.InvalidStateError: invalid state
2025-07-27 09:44:30.207 ERROR (MainThread) [homeassistant] Error doing job: Exception in callback RoborockFuture._set_result() (None)
Traceback (most recent call last):
  File "/usr/local/lib/python3.13/asyncio/events.py", line 89, in _run
    self._context.run(self._callback, *self._args)
    ~~~~~~~~~~~~~~~~~^^^^^^^^^^^^^^^^^^^^^^^^^^^^^
  File "/usr/local/lib/python3.13/site-packages/roborock/roborock_future.py", line 19, in _set_result
    self.fut.set_result(item)
    ~~~~~~~~~~~~~~~~~~~^^^^^^
asyncio.exceptions.InvalidStateError: invalid state
2025-07-27 09:44:30.211 ERROR (MainThread) [homeassistant] Error doing job: Exception in callback RoborockFuture._set_result() (None)
Traceback (most recent call last):
  File "/usr/local/lib/python3.13/asyncio/events.py", line 89, in _run
    self._context.run(self._callback, *self._args)
    ~~~~~~~~~~~~~~~~~^^^^^^^^^^^^^^^^^^^^^^^^^^^^^
  File "/usr/local/lib/python3.13/site-packages/roborock/roborock_future.py", line 19, in _set_result
    self.fut.set_result(item)
    ~~~~~~~~~~~~~~~~~~~^^^^^^
asyncio.exceptions.InvalidStateError: invalid state
2025-07-27 09:45:13.086 WARNING (MainThread) [roborock.version_1_apis.roborock_local_client_v1] [Q5 Max+] [Errno 104] Connection reset by peer
2025-07-27 09:45:13.286 WARNING (MainThread) [roborock.version_1_apis.roborock_local_client_v1] [Q5 Max+] Attempting to create a future with an existing id 2 (3)... New id is 28421. Code may not function properly.
2025-07-27 09:45:55.194 WARNING (MainThread) [roborock.version_1_apis.roborock_local_client_v1] [Q5 Max+] Attempting to create a future with an existing id 2 (3)... New id is 28429. Code may not function properly.
2025-07-27 09:46:26.079 WARNING (MainThread) [roborock.version_1_apis.roborock_local_client_v1] [Q5 Max+] Attempting to create a future with an existing id 2 (3)... New id is 28439. Code may not function properly.
2025-07-27 09:46:50.763 ERROR (MainThread) [homeassistant.components.roborock.coordinator] Error fetching roborock data: Failed to update data
2025-07-27 09:46:51.146 WARNING (MainThread) [roborock.version_1_apis.roborock_local_client_v1] [Q5 Max+] Attempting to create a future with an existing id 2 (3)... New id is 28443. Code may not function properly.
2025-07-27 09:47:59.032 WARNING (MainThread) [roborock.version_1_apis.roborock_local_client_v1] [Q5 Max+] [Errno 104] Connection reset by peer
2025-07-27 09:49:44.254 ERROR (MainThread) [homeassistant.components.roborock.coordinator] Error fetching roborock data: Failed to update data
2025-07-27 09:52:04.763 ERROR (MainThread) [homeassistant.components.roborock.coordinator] Error fetching roborock data: Failed to update data
2025-07-27 09:55:39.761 ERROR (MainThread) [homeassistant.components.roborock.coordinator] Error fetching roborock data: Failed to update data
2025-07-27 09:56:01.240 WARNING (MainThread) [roborock.version_1_apis.roborock_local_client_v1] [Q5 Max+] [Errno 104] Connection reset by peer
2025-07-27 09:58:45.773 ERROR (MainThread) [homeassistant.components.roborock.coordinator] Error fetching roborock data: Failed to update data
2025-07-27 10:01:07.254 WARNING (MainThread) [roborock.version_1_apis.roborock_local_client_v1] [Q5 Max+] [Errno 104] Connection reset by peer
2025-07-27 10:05:19.763 ERROR (MainThread) [homeassistant.components.roborock.coordinator] Error fetching roborock data: Failed to update data
2025-07-27 10:07:24.762 ERROR (MainThread) [homeassistant.components.roborock.coordinator] Error fetching roborock data: Failed to update data
2025-07-27 10:07:37.223 ERROR (MainThread) [homeassistant] Error doing job: Exception in callback RoborockFuture._set_result() (None)
Traceback (most recent call last):
  File "/usr/local/lib/python3.13/asyncio/events.py", line 89, in _run
    self._context.run(self._callback, *self._args)
    ~~~~~~~~~~~~~~~~~^^^^^^^^^^^^^^^^^^^^^^^^^^^^^
  File "/usr/local/lib/python3.13/site-packages/roborock/roborock_future.py", line 19, in _set_result
    self.fut.set_result(item)
    ~~~~~~~~~~~~~~~~~~~^^^^^^
asyncio.exceptions.InvalidStateError: invalid state
2025-07-27 10:09:29.762 ERROR (MainThread) [homeassistant.components.roborock.coordinator] Error fetching roborock data: Failed to update data
2025-07-27 10:09:30.145 WARNING (MainThread) [roborock.version_1_apis.roborock_local_client_v1] [Q5 Max+] [Errno 104] Connection reset by peer
2025-07-27 10:17:30.849 ERROR (MainThread) [homeassistant.components.roborock.coordinator] Error fetching roborock data: Failed to update data
2025-07-27 10:18:35.005 ERROR (MainThread) [homeassistant] Error doing job: Exception in callback RoborockFuture._set_result() (None)
Traceback (most recent call last):
  File "/usr/local/lib/python3.13/asyncio/events.py", line 89, in _run
    self._context.run(self._callback, *self._args)
    ~~~~~~~~~~~~~~~~~^^^^^^^^^^^^^^^^^^^^^^^^^^^^^
  File "/usr/local/lib/python3.13/site-packages/roborock/roborock_future.py", line 19, in _set_result
    self.fut.set_result(item)
    ~~~~~~~~~~~~~~~~~~~^^^^^^
asyncio.exceptions.InvalidStateError: invalid state
2025-07-27 10:19:43.760 ERROR (MainThread) [homeassistant.components.roborock.coordinator] Error fetching roborock data: Failed to update data
2025-07-27 10:19:45.922 WARNING (MainThread) [roborock.version_1_apis.roborock_local_client_v1] [Q5 Max+] [Errno 104] Connection reset by peer
2025-07-27 10:21:49.760 ERROR (MainThread) [homeassistant.components.roborock.coordinator] Error fetching roborock data: Failed to update data
2025-07-27 10:21:55.739 WARNING (MainThread) [roborock.version_1_apis.roborock_local_client_v1] [Q5 Max+] [Errno 104] Connection reset by peer
2025-07-27 10:22:18.177 WARNING (MainThread) [roborock.version_1_apis.roborock_local_client_v1] [Q5 Max+] Attempting to create a future with an existing id 2 (3)... New id is 28866. Code may not function properly.
2025-07-27 10:22:53.281 WARNING (MainThread) [roborock.version_1_apis.roborock_local_client_v1] [Q5 Max+] Attempting to create a future with an existing id 2 (3)... New id is 28875. Code may not function properly.
2025-07-27 10:23:01.760 ERROR (MainThread) [homeassistant.components.roborock.coordinator] Error fetching roborock data: Failed to update data
2025-07-27 10:23:34.548 WARNING (MainThread) [roborock.version_1_apis.roborock_local_client_v1] [Q5 Max+] Attempting to create a future with an existing id 2 (3)... New id is 28883. Code may not function properly.
2025-07-27 10:24:27.637 WARNING (MainThread) [roborock.version_1_apis.roborock_local_client_v1] [Q5 Max+] Attempting to create a future with an existing id 2 (3)... New id is 28891. Code may not function properly.
2025-07-27 10:24:52.652 WARNING (MainThread) [roborock.version_1_apis.roborock_local_client_v1] [Q5 Max+] Attempting to create a future with an existing id 2 (3)... New id is 28898. Code may not function properly.
2025-07-27 10:25:07.659 WARNING (MainThread) [roborock.version_1_apis.roborock_local_client_v1] [Q5 Max+] Attempting to create a future with an existing id 2 (3)... New id is 28902. Code may not function properly.
2025-07-27 10:25:16.763 ERROR (MainThread) [homeassistant.components.roborock.coordinator] Error fetching roborock data: Failed to update data
2025-07-27 10:25:22.664 WARNING (MainThread) [roborock.version_1_apis.roborock_local_client_v1] [Q5 Max+] Attempting to create a future with an existing id 2 (3)... New id is 28905. Code may not function properly.
2025-07-27 10:25:37.670 WARNING (MainThread) [roborock.version_1_apis.roborock_local_client_v1] [Q5 Max+] Attempting to create a future with an existing id 2 (3)... New id is 28907. Code may not function properly.
2025-07-27 10:25:52.676 WARNING (MainThread) [roborock.version_1_apis.roborock_local_client_v1] [Q5 Max+] Attempting to create a future with an existing id 2 (3)... New id is 28912. Code may not function properly.
2025-07-27 10:26:07.683 WARNING (MainThread) [roborock.version_1_apis.roborock_local_client_v1] [Q5 Max+] Attempting to create a future with an existing id 2 (3)... New id is 28915. Code may not function properly.
2025-07-27 10:26:22.689 WARNING (MainThread) [roborock.version_1_apis.roborock_local_client_v1] [Q5 Max+] Attempting to create a future with an existing id 2 (3)... New id is 28919. Code may not function properly.
2025-07-27 10:26:37.695 WARNING (MainThread) [roborock.version_1_apis.roborock_local_client_v1] [Q5 Max+] Attempting to create a future with an existing id 2 (3)... New id is 28921. Code may not function properly.
2025-07-27 10:26:52.701 WARNING (MainThread) [roborock.version_1_apis.roborock_local_client_v1] [Q5 Max+] Attempting to create a future with an existing id 2 (3)... New id is 28923. Code may not function properly.
2025-07-27 10:27:07.708 WARNING (MainThread) [roborock.version_1_apis.roborock_local_client_v1] [Q5 Max+] Attempting to create a future with an existing id 2 (3)... New id is 28927. Code may not function properly.
2025-07-27 10:27:22.718 WARNING (MainThread) [roborock.version_1_apis.roborock_local_client_v1] [Q5 Max+] Attempting to create a future with an existing id 2 (3)... New id is 28931. Code may not function properly.
2025-07-27 10:27:37.723 WARNING (MainThread) [roborock.version_1_apis.roborock_local_client_v1] [Q5 Max+] Attempting to create a future with an existing id 2 (3)... New id is 28935. Code may not function properly.
2025-07-27 10:27:52.728 WARNING (MainThread) [roborock.version_1_apis.roborock_local_client_v1] [Q5 Max+] Attempting to create a future with an existing id 2 (3)... New id is 28937. Code may not function properly.
2025-07-27 10:28:07.734 WARNING (MainThread) [roborock.version_1_apis.roborock_local_client_v1] [Q5 Max+] Attempting to create a future with an existing id 2 (3)... New id is 28941. Code may not function properly.
2025-07-27 10:28:22.741 WARNING (MainThread) [roborock.version_1_apis.roborock_local_client_v1] [Q5 Max+] Attempting to create a future with an existing id 2 (3)... New id is 28945. Code may not function properly.
2025-07-27 10:28:37.747 WARNING (MainThread) [roborock.version_1_apis.roborock_local_client_v1] [Q5 Max+] Attempting to create a future with an existing id 2 (3)... New id is 28946. Code may not function properly.
2025-07-27 10:28:52.752 WARNING (MainThread) [roborock.version_1_apis.roborock_local_client_v1] [Q5 Max+] Attempting to create a future with an existing id 2 (3)... New id is 28950. Code may not function properly.
2025-07-27 10:29:07.758 WARNING (MainThread) [roborock.version_1_apis.roborock_local_client_v1] [Q5 Max+] Attempting to create a future with an existing id 2 (3)... New id is 28953. Code may not function properly.
2025-07-27 10:29:22.763 WARNING (MainThread) [roborock.version_1_apis.roborock_local_client_v1] [Q5 Max+] Attempting to create a future with an existing id 2 (3)... New id is 28958. Code may not function properly.
2025-07-27 10:29:37.769 WARNING (MainThread) [roborock.version_1_apis.roborock_local_client_v1] [Q5 Max+] Attempting to create a future with an existing id 2 (3)... New id is 28960. Code may not function properly.
2025-07-27 10:29:52.776 WARNING (MainThread) [roborock.version_1_apis.roborock_local_client_v1] [Q5 Max+] Attempting to create a future with an existing id 2 (3)... New id is 28964. Code may not function properly.
2025-07-27 10:30:07.782 WARNING (MainThread) [roborock.version_1_apis.roborock_local_client_v1] [Q5 Max+] Attempting to create a future with an existing id 2 (3)... New id is 28966. Code may not function properly.
2025-07-27 10:30:22.789 WARNING (MainThread) [roborock.version_1_apis.roborock_local_client_v1] [Q5 Max+] Attempting to create a future with an existing id 2 (3)... New id is 28968. Code may not function properly.
2025-07-27 10:30:37.795 WARNING (MainThread) [roborock.version_1_apis.roborock_local_client_v1] [Q5 Max+] Attempting to create a future with an existing id 2 (3)... New id is 28974. Code may not function properly.
2025-07-27 10:30:52.801 WARNING (MainThread) [roborock.version_1_apis.roborock_local_client_v1] [Q5 Max+] Attempting to create a future with an existing id 2 (3)... New id is 28976. Code may not function properly.
2025-07-27 10:31:07.805 WARNING (MainThread) [roborock.version_1_apis.roborock_local_client_v1] [Q5 Max+] Attempting to create a future with an existing id 2 (3)... New id is 28980. Code may not function properly.
2025-07-27 10:31:22.812 WARNING (MainThread) [roborock.version_1_apis.roborock_local_client_v1] [Q5 Max+] Attempting to create a future with an existing id 2 (3)... New id is 28982. Code may not function properly.
2025-07-27 10:31:37.816 WARNING (MainThread) [roborock.version_1_apis.roborock_local_client_v1] [Q5 Max+] Attempting to create a future with an existing id 2 (3)... New id is 28988. Code may not function properly.
2025-07-27 10:31:52.821 WARNING (MainThread) [roborock.version_1_apis.roborock_local_client_v1] [Q5 Max+] Attempting to create a future with an existing id 2 (3)... New id is 28989. Code may not function properly.
2025-07-27 10:32:07.825 WARNING (MainThread) [roborock.version_1_apis.roborock_local_client_v1] [Q5 Max+] Attempting to create a future with an existing id 2 (3)... New id is 28991. Code may not function properly.
2025-07-27 10:32:22.830 WARNING (MainThread) [roborock.version_1_apis.roborock_local_client_v1] [Q5 Max+] Attempting to create a future with an existing id 2 (3)... New id is 28996. Code may not function properly.
2025-07-27 10:32:37.837 WARNING (MainThread) [roborock.version_1_apis.roborock_local_client_v1] [Q5 Max+] Attempting to create a future with an existing id 2 (3)... New id is 28999. Code may not function properly.
2025-07-27 10:32:52.843 WARNING (MainThread) [roborock.version_1_apis.roborock_local_client_v1] [Q5 Max+] Attempting to create a future with an existing id 2 (3)... New id is 29003. Code may not function properly.
2025-07-27 10:33:04.852 WARNING (MainThread) [roborock.version_1_apis.roborock_local_client_v1] [Q5 Max+] [Errno 104] Connection reset by peer
2025-07-27 10:33:17.163 WARNING (MainThread) [roborock.version_1_apis.roborock_local_client_v1] [Q5 Max+] Attempting to create a future with an existing id 2 (3)... New id is 29006. Code may not function properly.
2025-07-27 10:33:22.037 ERROR (MainThread) [homeassistant] Error doing job: Exception in callback RoborockFuture._set_result() (None)
Traceback (most recent call last):
  File "/usr/local/lib/python3.13/asyncio/events.py", line 89, in _run
    self._context.run(self._callback, *self._args)
    ~~~~~~~~~~~~~~~~~^^^^^^^^^^^^^^^^^^^^^^^^^^^^^
  File "/usr/local/lib/python3.13/site-packages/roborock/roborock_future.py", line 19, in _set_result
    self.fut.set_result(item)
    ~~~~~~~~~~~~~~~~~~~^^^^^^
asyncio.exceptions.InvalidStateError: invalid state
2025-07-27 10:33:32.169 WARNING (MainThread) [roborock.version_1_apis.roborock_local_client_v1] [Q5 Max+] Attempting to create a future with an existing id 2 (3)... New id is 29012. Code may not function properly.
2025-07-27 10:33:47.174 WARNING (MainThread) [roborock.version_1_apis.roborock_local_client_v1] [Q5 Max+] Attempting to create a future with an existing id 2 (3)... New id is 29016. Code may not function properly.
2025-07-27 10:34:00.443 ERROR (MainThread) [homeassistant.components.roborock.coordinator] Error fetching roborock data: Failed to update data
2025-07-27 10:34:02.178 WARNING (MainThread) [roborock.version_1_apis.roborock_local_client_v1] [Q5 Max+] Attempting to create a future with an existing id 2 (3)... New id is 29020. Code may not function properly.
2025-07-27 10:34:17.183 WARNING (MainThread) [roborock.version_1_apis.roborock_local_client_v1] [Q5 Max+] Attempting to create a future with an existing id 2 (3)... New id is 29022. Code may not function properly.
2025-07-27 10:34:29.625 WARNING (MainThread) [roborock.version_1_apis.roborock_local_client_v1] [Q5 Max+] [Errno 104] Connection reset by peer
2025-07-27 10:35:23.294 WARNING (MainThread) [roborock.version_1_apis.roborock_local_client_v1] [Q5 Max+] [Errno 104] Connection reset by peer
2025-07-27 10:35:35.914 WARNING (MainThread) [roborock.version_1_apis.roborock_local_client_v1] [Q5 Max+] Attempting to create a future with an existing id 2 (3)... New id is 29037. Code may not function properly.
2025-07-27 10:35:50.919 WARNING (MainThread) [roborock.version_1_apis.roborock_local_client_v1] [Q5 Max+] Attempting to create a future with an existing id 2 (3)... New id is 29042. Code may not function properly.
2025-07-27 10:36:05.923 WARNING (MainThread) [roborock.version_1_apis.roborock_local_client_v1] [Q5 Max+] Attempting to create a future with an existing id 2 (3)... New id is 29044. Code may not function properly.
2025-07-27 10:36:20.927 WARNING (MainThread) [roborock.version_1_apis.roborock_local_client_v1] [Q5 Max+] Attempting to create a future with an existing id 2 (3)... New id is 29048. Code may not function properly.
2025-07-27 10:36:35.932 WARNING (MainThread) [roborock.version_1_apis.roborock_local_client_v1] [Q5 Max+] Attempting to create a future with an existing id 2 (3)... New id is 29051. Code may not function properly.
2025-07-27 10:36:50.937 WARNING (MainThread) [roborock.version_1_apis.roborock_local_client_v1] [Q5 Max+] Attempting to create a future with an existing id 2 (3)... New id is 29054. Code may not function properly.
2025-07-27 10:37:05.940 WARNING (MainThread) [roborock.version_1_apis.roborock_local_client_v1] [Q5 Max+] Attempting to create a future with an existing id 2 (3)... New id is 29058. Code may not function properly.
2025-07-27 10:37:16.934 WARNING (MainThread) [roborock.version_1_apis.roborock_local_client_v1] [Q5 Max+] [Errno 104] Connection reset by peer
2025-07-27 10:37:26.521 ERROR (MainThread) [roborock.version_1_apis.roborock_local_client_v1] [Q5 Max+] id=1 Timeout after 5 seconds
2025-07-27 10:37:40.681 WARNING (MainThread) [roborock.version_1_apis.roborock_local_client_v1] [Q5 Max+] Attempting to create a future with an existing id 2 (3)... New id is 29064. Code may not function properly.
2025-07-27 10:37:55.686 WARNING (MainThread) [roborock.version_1_apis.roborock_local_client_v1] [Q5 Max+] Attempting to create a future with an existing id 2 (3)... New id is 29065. Code may not function properly.
2025-07-27 10:38:10.692 WARNING (MainThread) [roborock.version_1_apis.roborock_local_client_v1] [Q5 Max+] Attempting to create a future with an existing id 2 (3)... New id is 29071. Code may not function properly.
2025-07-27 10:38:25.698 WARNING (MainThread) [roborock.version_1_apis.roborock_local_client_v1] [Q5 Max+] Attempting to create a future with an existing id 2 (3)... New id is 29072. Code may not function properly.
2025-07-27 10:38:40.702 WARNING (MainThread) [roborock.version_1_apis.roborock_local_client_v1] [Q5 Max+] Attempting to create a future with an existing id 2 (3)... New id is 29077. Code may not function properly.
2025-07-27 10:38:55.709 WARNING (MainThread) [roborock.version_1_apis.roborock_local_client_v1] [Q5 Max+] Attempting to create a future with an existing id 2 (3)... New id is 29079. Code may not function properly.
2025-07-27 10:39:10.716 WARNING (MainThread) [roborock.version_1_apis.roborock_local_client_v1] [Q5 Max+] Attempting to create a future with an existing id 2 (3)... New id is 29082. Code may not function properly.
2025-07-27 10:39:25.723 WARNING (MainThread) [roborock.version_1_apis.roborock_local_client_v1] [Q5 Max+] Attempting to create a future with an existing id 2 (3)... New id is 29086. Code may not function properly.
2025-07-27 10:39:40.726 WARNING (MainThread) [roborock.version_1_apis.roborock_local_client_v1] [Q5 Max+] Attempting to create a future with an existing id 2 (3)... New id is 29088. Code may not function properly.
2025-07-27 10:39:55.731 WARNING (MainThread) [roborock.version_1_apis.roborock_local_client_v1] [Q5 Max+] Attempting to create a future with an existing id 2 (3)... New id is 29093. Code may not function properly.
2025-07-27 10:40:10.738 WARNING (MainThread) [roborock.version_1_apis.roborock_local_client_v1] [Q5 Max+] Attempting to create a future with an existing id 2 (3)... New id is 29096. Code may not function properly.
2025-07-27 10:40:25.744 WARNING (MainThread) [roborock.version_1_apis.roborock_local_client_v1] [Q5 Max+] Attempting to create a future with an existing id 2 (3)... New id is 29100. Code may not function properly.
2025-07-27 10:40:40.749 WARNING (MainThread) [roborock.version_1_apis.roborock_local_client_v1] [Q5 Max+] Attempting to create a future with an existing id 2 (3)... New id is 29101. Code may not function properly.
2025-07-27 10:40:55.760 WARNING (MainThread) [roborock.version_1_apis.roborock_local_client_v1] [Q5 Max+] Attempting to create a future with an existing id 2 (3)... New id is 29107. Code may not function properly.
2025-07-27 10:40:57.699 WARNING (MainThread) [roborock.version_1_apis.roborock_local_client_v1] [Q5 Max+] [Errno 104] Connection reset by peer
2025-07-27 10:46:18.763 ERROR (MainThread) [homeassistant.components.roborock.coordinator] Error fetching roborock data: Failed to update data
2025-07-27 10:48:56.512 WARNING (MainThread) [roborock.version_1_apis.roborock_local_client_v1] [Q5 Max+] [Errno 104] Connection reset by peer
2025-07-27 10:52:23.762 ERROR (MainThread) [homeassistant.components.roborock.coordinator] Error fetching roborock data: Failed to update data
2025-07-27 10:52:25.123 WARNING (MainThread) [roborock.version_1_apis.roborock_local_client_v1] [Q5 Max+] [Errno 104] Connection reset by peer
2025-07-27 10:55:29.984 WARNING (MainThread) [roborock.version_1_apis.roborock_local_client_v1] [Q5 Max+] [Errno 104] Connection reset by peer
2025-07-27 10:55:33.762 ERROR (MainThread) [homeassistant.components.roborock.coordinator] Error fetching roborock data: Failed to update data
2025-07-27 10:55:53.040 WARNING (MainThread) [roborock.version_1_apis.roborock_local_client_v1] [Q5 Max+] Attempting to create a future with an existing id 2 (3)... New id is 29268. Code may not function properly.
2025-07-27 10:58:10.761 ERROR (MainThread) [homeassistant.components.roborock.coordinator] Error fetching roborock data: Failed to update data
2025-07-27 10:58:29.191 WARNING (MainThread) [roborock.version_1_apis.roborock_local_client_v1] [Q5 Max+] [Errno 104] Connection reset by peer
2025-07-27 11:04:01.957 WARNING (MainThread) [roborock.version_1_apis.roborock_local_client_v1] [Q5 Max+] [Errno 104] Connection reset by peer
2025-07-27 11:06:09.987 WARNING (MainThread) [roborock.version_1_apis.roborock_local_client_v1] [Q5 Max+] [Errno 104] Connection reset by peer
2025-07-27 11:06:11.762 ERROR (MainThread) [homeassistant.components.roborock.coordinator] Error fetching roborock data: Failed to update data
2025-07-27 11:08:05.548 WARNING (MainThread) [roborock.version_1_apis.roborock_local_client_v1] [Q5 Max+] [Errno 104] Connection reset by peer
2025-07-27 11:11:55.763 ERROR (MainThread) [homeassistant.components.roborock.coordinator] Error fetching roborock data: Failed to update data
2025-07-27 11:14:24.508 WARNING (MainThread) [roborock.version_1_apis.roborock_local_client_v1] [Q5 Max+] [Errno 104] Connection reset by peer
2025-07-27 11:14:25.962 WARNING (MainThread) [roborock.version_1_apis.roborock_local_client_v1] [Q5 Max+] Attempting to create a future with an existing id 2 (3)... New id is 29476. Code may not function properly.
2025-07-27 11:15:54.762 ERROR (MainThread) [homeassistant.components.roborock.coordinator] Error fetching roborock data: Failed to update data
2025-07-27 11:15:56.087 WARNING (MainThread) [roborock.version_1_apis.roborock_local_client_v1] [Q5 Max+] [Errno 104] Connection reset by peer
2025-07-27 11:19:16.760 ERROR (MainThread) [homeassistant.components.roborock.coordinator] Error fetching roborock data: Failed to update data
2025-07-27 11:19:33.475 WARNING (MainThread) [roborock.version_1_apis.roborock_local_client_v1] [Q5 Max+] [Errno 104] Connection reset by peer
2025-07-27 12:39:33.763 ERROR (MainThread) [homeassistant.components.roborock.coordinator] Error fetching roborock data: Failed to update data
2025-07-27 14:03:17.761 ERROR (MainThread) [homeassistant.components.roborock.coordinator] Error fetching roborock data: Failed to update data
2025-07-27 14:05:54.763 ERROR (MainThread) [homeassistant.components.roborock.coordinator] Error fetching roborock data: Failed to update data
2025-07-27 14:06:15.630 WARNING (MainThread) [roborock.version_1_apis.roborock_local_client_v1] [Q5 Max+] [Errno 104] Connection reset by peer
2025-07-27 14:06:16.637 WARNING (MainThread) [roborock.version_1_apis.roborock_local_client_v1] [Q5 Max+] Attempting to create a future with an existing id 2 (3)... New id is 31857. Code may not function properly.
2025-07-27 14:06:51.729 WARNING (MainThread) [roborock.version_1_apis.roborock_local_client_v1] [Q5 Max+] Attempting to create a future with an existing id 2 (3)... New id is 31862. Code may not function properly.
2025-07-27 14:06:59.766 ERROR (MainThread) [homeassistant.components.roborock.coordinator] Error fetching roborock data: Failed to update data
2025-07-27 14:07:35.611 WARNING (MainThread) [roborock.version_1_apis.roborock_local_client_v1] [Q5 Max+] [Errno 104] Connection reset by peer
2025-07-27 14:08:36.949 WARNING (MainThread) [roborock.version_1_apis.roborock_local_client_v1] [Q5 Max+] Attempting to create a future with an existing id 2 (3)... New id is 31885. Code may not function properly.
2025-07-27 14:08:38.348 ERROR (MainThread) [homeassistant] Error doing job: Exception in callback RoborockFuture._set_result() (None)
Traceback (most recent call last):
  File "/usr/local/lib/python3.13/asyncio/events.py", line 89, in _run
    self._context.run(self._callback, *self._args)
    ~~~~~~~~~~~~~~~~~^^^^^^^^^^^^^^^^^^^^^^^^^^^^^
  File "/usr/local/lib/python3.13/site-packages/roborock/roborock_future.py", line 19, in _set_result
    self.fut.set_result(item)
    ~~~~~~~~~~~~~~~~~~~^^^^^^
asyncio.exceptions.InvalidStateError: invalid state
2025-07-27 14:10:41.993 WARNING (MainThread) [roborock.version_1_apis.roborock_local_client_v1] [Q5 Max+] Attempting to create a future with an existing id 2 (3)... New id is 31914. Code may not function properly.
2025-07-27 14:10:46.763 ERROR (MainThread) [homeassistant.components.roborock.coordinator] Error fetching roborock data: Failed to update data
2025-07-27 14:12:48.263 WARNING (MainThread) [roborock.version_1_apis.roborock_local_client_v1] [Q5 Max+] Attempting to create a future with an existing id 2 (3)... New id is 31937. Code may not function properly.
2025-07-27 14:14:33.916 WARNING (MainThread) [roborock.version_1_apis.roborock_local_client_v1] [Q5 Max+] Attempting to create a future with an existing id 2 (3)... New id is 31966. Code may not function properly.
2025-07-27 14:14:34.553 ERROR (MainThread) [homeassistant] Error doing job: Exception in callback RoborockFuture._set_result() (None)
Traceback (most recent call last):
  File "/usr/local/lib/python3.13/asyncio/events.py", line 89, in _run
    self._context.run(self._callback, *self._args)
    ~~~~~~~~~~~~~~~~~^^^^^^^^^^^^^^^^^^^^^^^^^^^^^
  File "/usr/local/lib/python3.13/site-packages/roborock/roborock_future.py", line 19, in _set_result
    self.fut.set_result(item)
    ~~~~~~~~~~~~~~~~~~~^^^^^^
asyncio.exceptions.InvalidStateError: invalid state
2025-07-27 14:15:44.472 WARNING (MainThread) [roborock.version_1_apis.roborock_local_client_v1] [Q5 Max+] Attempting to create a future with an existing id 2 (3)... New id is 31981. Code may not function properly.
2025-07-27 14:16:19.519 WARNING (MainThread) [roborock.version_1_apis.roborock_local_client_v1] [Q5 Max+] Attempting to create a future with an existing id 2 (3)... New id is 31989. Code may not function properly.
2025-07-27 14:16:33.740 ERROR (MainThread) [homeassistant] Error doing job: Exception in callback RoborockFuture._set_result() (None)
Traceback (most recent call last):
  File "/usr/local/lib/python3.13/asyncio/events.py", line 89, in _run
    self._context.run(self._callback, *self._args)
    ~~~~~~~~~~~~~~~~~^^^^^^^^^^^^^^^^^^^^^^^^^^^^^
  File "/usr/local/lib/python3.13/site-packages/roborock/roborock_future.py", line 19, in _set_result
    self.fut.set_result(item)
    ~~~~~~~~~~~~~~~~~~~^^^^^^
asyncio.exceptions.InvalidStateError: invalid state
2025-07-27 14:16:33.744 ERROR (MainThread) [homeassistant] Error doing job: Exception in callback RoborockFuture._set_result() (None)
Traceback (most recent call last):
  File "/usr/local/lib/python3.13/asyncio/events.py", line 89, in _run
    self._context.run(self._callback, *self._args)
    ~~~~~~~~~~~~~~~~~^^^^^^^^^^^^^^^^^^^^^^^^^^^^^
  File "/usr/local/lib/python3.13/site-packages/roborock/roborock_future.py", line 19, in _set_result
    self.fut.set_result(item)
    ~~~~~~~~~~~~~~~~~~~^^^^^^
asyncio.exceptions.InvalidStateError: invalid state
2025-07-27 14:16:54.620 WARNING (MainThread) [roborock.version_1_apis.roborock_local_client_v1] [Q5 Max+] Attempting to create a future with an existing id 2 (3)... New id is 31997. Code may not function properly.
2025-07-27 14:26:21.539 WARNING (MainThread) [roborock.version_1_apis.roborock_local_client_v1] [Q5 Max+] Attempting to create a future with an existing id 2 (3)... New id is 32131. Code may not function properly.
2025-07-27 14:27:26.730 WARNING (MainThread) [roborock.version_1_apis.roborock_local_client_v1] [Q5 Max+] Attempting to create a future with an existing id 2 (3)... New id is 32146. Code may not function properly.
2025-07-27 14:27:36.776 WARNING (MainThread) [roborock.version_1_apis.roborock_local_client_v1] [Q5 Max+] [Errno 104] Connection reset by peer
2025-07-27 14:27:47.240 WARNING (MainThread) [roborock.version_1_apis.roborock_local_client_v1] [Q5 Max+] Attempting to create a future with an existing id 2 (3)... New id is 32154. Code may not function properly.
2025-07-27 14:30:50.761 ERROR (MainThread) [homeassistant.components.roborock.coordinator] Error fetching roborock data: Failed to update data
2025-07-27 14:35:39.515 WARNING (MainThread) [roborock.version_1_apis.roborock_local_client_v1] [Q5 Max+] Attempting to create a future with an existing id 2 (3)... New id is 32258. Code may not function properly.
2025-07-27 15:54:01.762 ERROR (MainThread) [homeassistant.components.roborock.coordinator] Error fetching roborock data: Failed to update data
2025-07-27 15:54:02.024 WARNING (MainThread) [roborock.version_1_apis.roborock_local_client_v1] [Q5 Max+] Attempting to create a future with an existing id 2 (3)... New id is 33356. Code may not function properly.
2025-07-27 15:54:17.030 WARNING (MainThread) [roborock.version_1_apis.roborock_local_client_v1] [Q5 Max+] Attempting to create a future with an existing id 2 (3)... New id is 33358. Code may not function properly.
2025-07-27 15:54:32.034 WARNING (MainThread) [roborock.version_1_apis.roborock_local_client_v1] [Q5 Max+] Attempting to create a future with an existing id 2 (3)... New id is 33361. Code may not function properly.
2025-07-27 15:54:47.040 WARNING (MainThread) [roborock.version_1_apis.roborock_local_client_v1] [Q5 Max+] Attempting to create a future with an existing id 2 (3)... New id is 33366. Code may not function properly.
2025-07-27 15:54:52.734 WARNING (MainThread) [roborock.version_1_apis.roborock_local_client_v1] [Q5 Max+] [Errno 104] Connection reset by peer
2025-07-27 15:55:10.460 WARNING (MainThread) [roborock.version_1_apis.roborock_local_client_v1] [Q5 Max+] Attempting to create a future with an existing id 2 (3)... New id is 33372. Code may not function properly.
2025-07-27 17:16:17.828 WARNING (MainThread) [roborock.version_1_apis.roborock_local_client_v1] [Q5 Max+] Attempting to create a future with an existing id 2 (3)... New id is 34508. Code may not function properly.
2025-07-27 17:23:45.140 ERROR (MainThread) [homeassistant.components.roborock.coordinator] Error fetching roborock data: Failed to update data
2025-07-27 17:23:59.180 WARNING (MainThread) [roborock.version_1_apis.roborock_local_client_v1] [Q5 Max+] Attempting to create a future with an existing id 2 (3)... New id is 34616. Code may not function properly.
2025-07-27 17:24:10.686 ERROR (MainThread) [homeassistant] Error doing job: Exception in callback RoborockFuture._set_result() (None)
Traceback (most recent call last):
  File "/usr/local/lib/python3.13/asyncio/events.py", line 89, in _run
    self._context.run(self._callback, *self._args)
    ~~~~~~~~~~~~~~~~~^^^^^^^^^^^^^^^^^^^^^^^^^^^^^
  File "/usr/local/lib/python3.13/site-packages/roborock/roborock_future.py", line 19, in _set_result
    self.fut.set_result(item)
    ~~~~~~~~~~~~~~~~~~~^^^^^^
asyncio.exceptions.InvalidStateError: invalid state
2025-07-27 17:25:33.758 ERROR (MainThread) [homeassistant.components.roborock.coordinator] Error fetching roborock data: Failed to update data
2025-07-27 17:25:59.611 ERROR (MainThread) [roborock.version_1_apis.roborock_local_client_v1] [Q5 Max+] id=1 Timeout after 5 seconds
2025-07-27 17:43:55.763 ERROR (MainThread) [homeassistant.components.roborock.coordinator] Error fetching roborock data: Failed to update data
2025-07-27 18:48:05.762 ERROR (MainThread) [homeassistant.components.roborock.coordinator] Error fetching roborock data: Failed to update data
2025-07-27 18:48:33.053 ERROR (MainThread) [homeassistant] Error doing job: Exception in callback RoborockFuture._set_result() (None)
Traceback (most recent call last):
  File "/usr/local/lib/python3.13/asyncio/events.py", line 89, in _run
    self._context.run(self._callback, *self._args)
    ~~~~~~~~~~~~~~~~~^^^^^^^^^^^^^^^^^^^^^^^^^^^^^
  File "/usr/local/lib/python3.13/site-packages/roborock/roborock_future.py", line 19, in _set_result
    self.fut.set_result(item)
    ~~~~~~~~~~~~~~~~~~~^^^^^^
asyncio.exceptions.InvalidStateError: invalid state
2025-07-27 18:48:33.056 ERROR (MainThread) [homeassistant] Error doing job: Exception in callback RoborockFuture._set_result() (None)
Traceback (most recent call last):
  File "/usr/local/lib/python3.13/asyncio/events.py", line 89, in _run
    self._context.run(self._callback, *self._args)
    ~~~~~~~~~~~~~~~~~^^^^^^^^^^^^^^^^^^^^^^^^^^^^^
  File "/usr/local/lib/python3.13/site-packages/roborock/roborock_future.py", line 19, in _set_result
    self.fut.set_result(item)
    ~~~~~~~~~~~~~~~~~~~^^^^^^
asyncio.exceptions.InvalidStateError: invalid state
2025-07-27 18:59:15.764 ERROR (MainThread) [homeassistant.components.roborock.coordinator] Error fetching roborock data: Failed to update data
2025-07-27 19:00:52.776 ERROR (MainThread) [homeassistant.components.roborock.coordinator] Error fetching roborock data: Failed to update data
2025-07-27 19:05:33.763 ERROR (MainThread) [homeassistant.components.roborock.coordinator] Error fetching roborock data: Failed to update data
2025-07-27 19:45:34.762 ERROR (MainThread) [homeassistant.components.roborock.coordinator] Error fetching roborock data: Failed to update data
2025-07-27 19:46:00.579 WARNING (MainThread) [roborock.version_1_apis.roborock_local_client_v1] [Q5 Max+] [Errno 104] Connection reset by peer
2025-07-27 19:48:09.760 ERROR (MainThread) [homeassistant.components.roborock.coordinator] Error fetching roborock data: Failed to update data
2025-07-27 19:48:35.330 WARNING (MainThread) [roborock.version_1_apis.roborock_local_client_v1] [Q5 Max+] [Errno 104] Connection reset by peer
2025-07-27 19:49:15.762 ERROR (MainThread) [homeassistant.components.roborock.coordinator] Error fetching roborock data: Failed to update data
2025-07-27 19:51:17.188 WARNING (MainThread) [roborock.version_1_apis.roborock_local_client_v1] [Q5 Max+] [Errno 104] Connection reset by peer
2025-07-27 19:51:18.155 WARNING (MainThread) [roborock.version_1_apis.roborock_local_client_v1] [Q5 Max+] Attempting to create a future with an existing id 2 (3)... New id is 36617. Code may not function properly.
2025-07-27 19:53:05.762 ERROR (MainThread) [homeassistant.components.roborock.coordinator] Error fetching roborock data: Failed to update data
2025-07-27 19:54:33.870 WARNING (MainThread) [roborock.version_1_apis.roborock_local_client_v1] [Q5 Max+] [Errno 104] Connection reset by peer
2025-07-27 20:49:37.762 ERROR (MainThread) [homeassistant.components.roborock.coordinator] Error fetching roborock data: Failed to update data
2025-07-27 20:54:54.761 ERROR (MainThread) [homeassistant.components.roborock.coordinator] Error fetching roborock data: Failed to update data
2025-07-27 20:58:00.762 ERROR (MainThread) [homeassistant.components.roborock.coordinator] Error fetching roborock data: Failed to update data
2025-07-27 20:58:03.418 WARNING (MainThread) [roborock.version_1_apis.roborock_local_client_v1] [Q5 Max+] [Errno 104] Connection reset by peer
2025-07-27 20:59:29.214 WARNING (MainThread) [roborock.version_1_apis.roborock_local_client_v1] [Q5 Max+] [Errno 104] Connection reset by peer
2025-07-27 21:02:38.762 ERROR (MainThread) [homeassistant.components.roborock.coordinator] Error fetching roborock data: Failed to update data
2025-07-27 21:03:08.786 WARNING (MainThread) [roborock.version_1_apis.roborock_local_client_v1] [Q5 Max+] Attempting to create a future with an existing id 2 (3)... New id is 37599. Code may not function properly.
2025-07-27 21:04:18.763 ERROR (MainThread) [homeassistant.components.roborock.coordinator] Error fetching roborock data: Failed to update data
2025-07-27 21:05:47.873 WARNING (MainThread) [roborock.version_1_apis.roborock_local_client_v1] [Q5 Max+] [Errno 104] Connection reset by peer
2025-07-27 21:07:03.762 ERROR (MainThread) [homeassistant.components.roborock.coordinator] Error fetching roborock data: Failed to update data
2025-07-27 21:07:09.333 WARNING (MainThread) [roborock.version_1_apis.roborock_local_client_v1] [Q5 Max+] [Errno 104] Connection reset by peer
2025-07-27 21:13:12.762 ERROR (MainThread) [homeassistant.components.roborock.coordinator] Error fetching roborock data: Failed to update data
2025-07-27 21:13:27.572 WARNING (MainThread) [roborock.version_1_apis.roborock_local_client_v1] [Q5 Max+] [Errno 104] Connection reset by peer
2025-07-27 21:13:48.942 WARNING (MainThread) [roborock.version_1_apis.roborock_local_client_v1] [Q5 Max+] Attempting to create a future with an existing id 2 (3)... New id is 37732. Code may not function properly.
2025-07-27 21:15:47.761 ERROR (MainThread) [homeassistant.components.roborock.coordinator] Error fetching roborock data: Failed to update data
2025-07-27 21:15:49.201 WARNING (MainThread) [roborock.version_1_apis.roborock_local_client_v1] [Q5 Max+] Attempting to create a future with an existing id 2 (3)... New id is 37759. Code may not function properly.
2025-07-27 21:15:49.917 ERROR (MainThread) [homeassistant] Error doing job: Exception in callback RoborockFuture._set_result() (None)
Traceback (most recent call last):
  File "/usr/local/lib/python3.13/asyncio/events.py", line 89, in _run
    self._context.run(self._callback, *self._args)
    ~~~~~~~~~~~~~~~~~^^^^^^^^^^^^^^^^^^^^^^^^^^^^^
  File "/usr/local/lib/python3.13/site-packages/roborock/roborock_future.py", line 19, in _set_result
    self.fut.set_result(item)
    ~~~~~~~~~~~~~~~~~~~^^^^^^
asyncio.exceptions.InvalidStateError: invalid state
2025-07-27 21:19:08.388 WARNING (MainThread) [roborock.version_1_apis.roborock_local_client_v1] [Q5 Max+] Attempting to create a future with an existing id 2 (3)... New id is 37807. Code may not function properly.
2025-07-27 21:19:23.396 WARNING (MainThread) [roborock.version_1_apis.roborock_local_client_v1] [Q5 Max+] Attempting to create a future with an existing id 2 (3)... New id is 37811. Code may not function properly.
2025-07-27 21:19:23.760 ERROR (MainThread) [homeassistant.components.roborock.coordinator] Error fetching roborock data: Failed to update data
2025-07-27 21:25:55.245 WARNING (MainThread) [roborock.version_1_apis.roborock_local_client_v1] [Q5 Max+] Attempting to create a future with an existing id 2 (3)... New id is 37897. Code may not function properly.
2025-07-27 21:31:36.511 WARNING (MainThread) [roborock.version_1_apis.roborock_local_client_v1] [Q5 Max+] Attempting to create a future with an existing id 2 (3)... New id is 37981. Code may not function properly.
2025-07-27 21:32:02.658 WARNING (MainThread) [roborock.version_1_apis.roborock_local_client_v1] [Q5 Max+] Attempting to create a future with an existing id 2 (3)... New id is 37985. Code may not function properly.
2025-07-27 21:32:37.756 WARNING (MainThread) [roborock.version_1_apis.roborock_local_client_v1] [Q5 Max+] Attempting to create a future with an existing id 2 (3)... New id is 37997. Code may not function properly.
2025-07-27 21:35:39.044 ERROR (MainThread) [homeassistant.components.roborock.coordinator] Error fetching roborock data: Failed to update data
2025-07-27 21:35:40.255 ERROR (MainThread) [homeassistant] Error doing job: Exception in callback RoborockFuture._set_result() (None)
Traceback (most recent call last):
  File "/usr/local/lib/python3.13/asyncio/events.py", line 89, in _run
    self._context.run(self._callback, *self._args)
    ~~~~~~~~~~~~~~~~~^^^^^^^^^^^^^^^^^^^^^^^^^^^^^
  File "/usr/local/lib/python3.13/site-packages/roborock/roborock_future.py", line 19, in _set_result
    self.fut.set_result(item)
    ~~~~~~~~~~~~~~~~~~~^^^^^^
asyncio.exceptions.InvalidStateError: invalid state
2025-07-27 21:35:50.263 WARNING (MainThread) [roborock.version_1_apis.roborock_local_client_v1] [Q5 Max+] Attempting to create a future with an existing id 2 (3)... New id is 38039. Code may not function properly.
2025-07-27 21:37:02.709 WARNING (MainThread) [roborock.version_1_apis.roborock_local_client_v1] [Q5 Max+] Attempting to create a future with an existing id 2 (3)... New id is 38055. Code may not function properly.
2025-07-27 21:37:17.715 WARNING (MainThread) [roborock.version_1_apis.roborock_local_client_v1] [Q5 Max+] Attempting to create a future with an existing id 2 (3)... New id is 38062. Code may not function properly.
2025-07-27 21:37:17.770 ERROR (MainThread) [homeassistant.components.roborock.coordinator] Error fetching roborock data: Failed to update data
2025-07-27 21:37:18.794 ERROR (MainThread) [homeassistant] Error doing job: Exception in callback RoborockFuture._set_result() (None)
Traceback (most recent call last):
  File "/usr/local/lib/python3.13/asyncio/events.py", line 89, in _run
    self._context.run(self._callback, *self._args)
    ~~~~~~~~~~~~~~~~~^^^^^^^^^^^^^^^^^^^^^^^^^^^^^
  File "/usr/local/lib/python3.13/site-packages/roborock/roborock_future.py", line 19, in _set_result
    self.fut.set_result(item)
    ~~~~~~~~~~~~~~~~~~~^^^^^^
asyncio.exceptions.InvalidStateError: invalid state
2025-07-27 21:43:11.422 WARNING (MainThread) [roborock.version_1_apis.roborock_local_client_v1] [Q5 Max+] Attempting to create a future with an existing id 2 (3)... New id is 38139. Code may not function properly.
2025-07-27 21:43:33.763 ERROR (MainThread) [homeassistant.components.roborock.coordinator] Error fetching roborock data: Failed to update data
2025-07-27 21:44:27.919 WARNING (MainThread) [roborock.version_1_apis.roborock_local_client_v1] [Q5 Max+] Attempting to create a future with an existing id 2 (3)... New id is 38156. Code may not function properly.
2025-07-27 21:49:48.333 WARNING (MainThread) [roborock.version_1_apis.roborock_local_client_v1] [Q5 Max+] Attempting to create a future with an existing id 2 (3)... New id is 38232. Code may not function properly.
2025-07-27 21:50:03.339 WARNING (MainThread) [roborock.version_1_apis.roborock_local_client_v1] [Q5 Max+] Attempting to create a future with an existing id 2 (3)... New id is 38233. Code may not function properly.
2025-07-27 21:50:13.761 ERROR (MainThread) [homeassistant.components.roborock.coordinator] Error fetching roborock data: Failed to update data
2025-07-27 21:50:18.345 WARNING (MainThread) [roborock.version_1_apis.roborock_local_client_v1] [Q5 Max+] Attempting to create a future with an existing id 2 (3)... New id is 38237. Code may not function properly.
2025-07-27 21:51:29.562 WARNING (MainThread) [roborock.version_1_apis.roborock_local_client_v1] [Q5 Max+] Attempting to create a future with an existing id 2 (3)... New id is 38256. Code may not function properly.
2025-07-27 21:52:34.710 WARNING (MainThread) [roborock.version_1_apis.roborock_local_client_v1] [Q5 Max+] Attempting to create a future with an existing id 2 (3)... New id is 38271. Code may not function properly.
2025-07-27 21:55:06.663 WARNING (MainThread) [roborock.version_1_apis.roborock_local_client_v1] [Q5 Max+] Attempting to create a future with an existing id 2 (3)... New id is 38305. Code may not function properly.
2025-07-27 21:55:21.668 WARNING (MainThread) [roborock.version_1_apis.roborock_local_client_v1] [Q5 Max+] Attempting to create a future with an existing id 2 (3)... New id is 38306. Code may not function properly.
2025-07-27 21:55:26.914 WARNING (MainThread) [roborock.version_1_apis.roborock_local_client_v1] [Q5 Max+] [Errno 104] Connection reset by peer
2025-07-27 21:55:27.762 ERROR (MainThread) [homeassistant.components.roborock.coordinator] Error fetching roborock data: Failed to update data
2025-07-27 21:55:41.799 WARNING (MainThread) [roborock.version_1_apis.roborock_local_client_v1] [Q5 Max+] Attempting to create a future with an existing id 2 (3)... New id is 38315. Code may not function properly.
2025-07-27 22:02:34.346 WARNING (MainThread) [roborock.version_1_apis.roborock_local_client_v1] [Q5 Max+] Attempting to create a future with an existing id 2 (3)... New id is 38411. Code may not function properly.
2025-07-27 22:02:34.762 ERROR (MainThread) [homeassistant.components.roborock.coordinator] Error fetching roborock data: Failed to update data
2025-07-27 22:02:49.352 WARNING (MainThread) [roborock.version_1_apis.roborock_local_client_v1] [Q5 Max+] Attempting to create a future with an existing id 2 (3)... New id is 38413. Code may not function properly.
2025-07-27 22:03:04.360 WARNING (MainThread) [roborock.version_1_apis.roborock_local_client_v1] [Q5 Max+] Attempting to create a future with an existing id 2 (3)... New id is 38414. Code may not function properly.
2025-07-27 22:03:19.365 WARNING (MainThread) [roborock.version_1_apis.roborock_local_client_v1] [Q5 Max+] Attempting to create a future with an existing id 2 (3)... New id is 38417. Code may not function properly.
2025-07-27 22:03:34.370 WARNING (MainThread) [roborock.version_1_apis.roborock_local_client_v1] [Q5 Max+] Attempting to create a future with an existing id 2 (3)... New id is 38423. Code may not function properly.
2025-07-27 22:03:49.374 WARNING (MainThread) [roborock.version_1_apis.roborock_local_client_v1] [Q5 Max+] Attempting to create a future with an existing id 2 (3)... New id is 38427. Code may not function properly.
2025-07-27 22:09:26.650 WARNING (MainThread) [roborock.version_1_apis.roborock_local_client_v1] [Q5 Max+] [Errno 104] Connection reset by peer
2025-07-27 22:18:22.762 ERROR (MainThread) [homeassistant.components.roborock.coordinator] Error fetching roborock data: Failed to update data
2025-07-27 22:19:45.973 WARNING (MainThread) [roborock.version_1_apis.roborock_local_client_v1] [Q5 Max+] [Errno 104] Connection reset by peer
2025-07-27 22:33:15.762 ERROR (MainThread) [homeassistant.components.roborock.coordinator] Error fetching roborock data: Failed to update data
2025-07-27 22:35:29.486 WARNING (MainThread) [roborock.version_1_apis.roborock_local_client_v1] [Q5 Max+] [Errno 104] Connection reset by peer
2025-07-27 22:35:32.762 ERROR (MainThread) [homeassistant.components.roborock.coordinator] Error fetching roborock data: Failed to update data
2025-07-27 22:41:37.762 ERROR (MainThread) [homeassistant.components.roborock.coordinator] Error fetching roborock data: Failed to update data
2025-07-27 22:42:08.632 WARNING (MainThread) [roborock.version_1_apis.roborock_local_client_v1] [Q5 Max+] Attempting to create a future with an existing id 2 (3)... New id is 38931. Code may not function properly.
2025-07-27 22:50:54.363 WARNING (MainThread) [roborock.version_1_apis.roborock_local_client_v1] [Q5 Max+] Attempting to create a future with an existing id 2 (3)... New id is 39051. Code may not function properly.
2025-07-27 22:51:09.369 WARNING (MainThread) [roborock.version_1_apis.roborock_local_client_v1] [Q5 Max+] Attempting to create a future with an existing id 2 (3)... New id is 39057. Code may not function properly.
2025-07-27 22:51:12.763 ERROR (MainThread) [homeassistant.components.roborock.coordinator] Error fetching roborock data: Failed to update data
2025-07-27 22:51:17.336 WARNING (MainThread) [roborock.version_1_apis.roborock_local_client_v1] [Q5 Max+] [Errno 104] Connection reset by peer
2025-07-27 22:51:29.540 WARNING (MainThread) [roborock.version_1_apis.roborock_local_client_v1] [Q5 Max+] Attempting to create a future with an existing id 2 (3)... New id is 39061. Code may not function properly.
2025-07-27 22:54:25.648 WARNING (MainThread) [roborock.version_1_apis.roborock_local_client_v1] [Q5 Max+] Attempting to create a future with an existing id 2 (3)... New id is 39102. Code may not function properly.
2025-07-27 23:04:57.219 WARNING (MainThread) [roborock.version_1_apis.roborock_local_client_v1] [Q5 Max+] Attempting to create a future with an existing id 2 (3)... New id is 39249. Code may not function properly.
2025-07-27 23:05:22.234 WARNING (MainThread) [roborock.version_1_apis.roborock_local_client_v1] [Q5 Max+] Attempting to create a future with an existing id 2 (3)... New id is 39258. Code may not function properly.
2025-07-27 23:05:37.241 WARNING (MainThread) [roborock.version_1_apis.roborock_local_client_v1] [Q5 Max+] Attempting to create a future with an existing id 2 (3)... New id is 39261. Code may not function properly.
2025-07-27 23:05:51.763 ERROR (MainThread) [homeassistant.components.roborock.coordinator] Error fetching roborock data: Failed to update data
2025-07-27 23:05:52.247 WARNING (MainThread) [roborock.version_1_apis.roborock_local_client_v1] [Q5 Max+] Attempting to create a future with an existing id 2 (3)... New id is 39264. Code may not function properly.
2025-07-27 23:07:59.367 WARNING (MainThread) [roborock.version_1_apis.roborock_local_client_v1] [Q5 Max+] Attempting to create a future with an existing id 2 (3)... New id is 39293. Code may not function properly.
2025-07-27 23:08:14.372 WARNING (MainThread) [roborock.version_1_apis.roborock_local_client_v1] [Q5 Max+] Attempting to create a future with an existing id 2 (3)... New id is 39297. Code may not function properly.
2025-07-27 23:08:26.761 ERROR (MainThread) [homeassistant.components.roborock.coordinator] Error fetching roborock data: Failed to update data
2025-07-27 23:08:29.378 WARNING (MainThread) [roborock.version_1_apis.roborock_local_client_v1] [Q5 Max+] Attempting to create a future with an existing id 2 (3)... New id is 39301. Code may not function properly.
2025-07-27 23:08:44.384 WARNING (MainThread) [roborock.version_1_apis.roborock_local_client_v1] [Q5 Max+] Attempting to create a future with an existing id 2 (3)... New id is 39304. Code may not function properly.
2025-07-27 23:08:54.477 WARNING (MainThread) [roborock.version_1_apis.roborock_local_client_v1] [Q5 Max+] [Errno 104] Connection reset by peer
2025-07-27 23:09:09.298 WARNING (MainThread) [roborock.version_1_apis.roborock_local_client_v1] [Q5 Max+] Attempting to create a future with an existing id 2 (3)... New id is 39309. Code may not function properly.
2025-07-27 23:09:24.302 WARNING (MainThread) [roborock.version_1_apis.roborock_local_client_v1] [Q5 Max+] Attempting to create a future with an existing id 2 (3)... New id is 39313. Code may not function properly.
2025-07-27 23:09:33.761 ERROR (MainThread) [homeassistant.components.roborock.coordinator] Error fetching roborock data: Failed to update data
2025-07-27 23:10:19.377 WARNING (MainThread) [roborock.version_1_apis.roborock_local_client_v1] [Q5 Max+] Attempting to create a future with an existing id 2 (3)... New id is 39326. Code may not function properly.
2025-07-27 23:13:36.598 WARNING (MainThread) [roborock.version_1_apis.roborock_local_client_v1] [Q5 Max+] Attempting to create a future with an existing id 2 (3)... New id is 39370. Code may not function properly.
2025-07-27 23:14:21.662 WARNING (MainThread) [roborock.version_1_apis.roborock_local_client_v1] [Q5 Max+] Attempting to create a future with an existing id 2 (3)... New id is 39384. Code may not function properly.
2025-07-27 23:14:36.667 WARNING (MainThread) [roborock.version_1_apis.roborock_local_client_v1] [Q5 Max+] Attempting to create a future with an existing id 2 (3)... New id is 39386. Code may not function properly.
2025-07-27 23:14:44.763 ERROR (MainThread) [homeassistant.components.roborock.coordinator] Error fetching roborock data: Failed to update data
2025-07-27 23:14:49.948 WARNING (MainThread) [roborock.version_1_apis.roborock_local_client_v1] [Q5 Max+] [Errno 104] Connection reset by peer
2025-07-27 23:15:14.571 WARNING (MainThread) [roborock.version_1_apis.roborock_local_client_v1] [Q5 Max+] Attempting to create a future with an existing id 2 (3)... New id is 39391. Code may not function properly.
2025-07-27 23:16:59.733 WARNING (MainThread) [roborock.version_1_apis.roborock_local_client_v1] [Q5 Max+] Attempting to create a future with an existing id 2 (3)... New id is 39420. Code may not function properly.
2025-07-27 23:17:14.739 WARNING (MainThread) [roborock.version_1_apis.roborock_local_client_v1] [Q5 Max+] Attempting to create a future with an existing id 2 (3)... New id is 39421. Code may not function properly.
2025-07-27 23:17:24.762 ERROR (MainThread) [homeassistant.components.roborock.coordinator] Error fetching roborock data: Failed to update data
2025-07-27 23:17:29.156 WARNING (MainThread) [roborock.version_1_apis.roborock_local_client_v1] [Q5 Max+] [Errno 104] Connection reset by peer
2025-07-27 23:17:39.550 WARNING (MainThread) [roborock.version_1_apis.roborock_local_client_v1] [Q5 Max+] Attempting to create a future with an existing id 2 (3)... New id is 39428. Code may not function properly.
2025-07-27 23:18:25.372 WARNING (MainThread) [roborock.version_1_apis.roborock_local_client_v1] [Q5 Max+] Attempting to create a future with an existing id 2 (3)... New id is 39440. Code may not function properly.
2025-07-27 23:18:29.762 ERROR (MainThread) [homeassistant.components.roborock.coordinator] Error fetching roborock data: Failed to update data
2025-07-27 23:18:40.375 WARNING (MainThread) [roborock.version_1_apis.roborock_local_client_v1] [Q5 Max+] Attempting to create a future with an existing id 2 (3)... New id is 39442. Code may not function properly.
2025-07-27 23:18:46.958 WARNING (MainThread) [roborock.version_1_apis.roborock_local_client_v1] [Q5 Max+] [Errno 104] Connection reset by peer
2025-07-27 23:19:21.401 WARNING (MainThread) [roborock.version_1_apis.roborock_local_client_v1] [Q5 Max+] Attempting to create a future with an existing id 2 (3)... New id is 39449. Code may not function properly.
2025-07-27 23:19:36.405 WARNING (MainThread) [roborock.version_1_apis.roborock_local_client_v1] [Q5 Max+] Attempting to create a future with an existing id 2 (3)... New id is 39457. Code may not function properly.
2025-07-27 23:22:51.606 WARNING (MainThread) [roborock.version_1_apis.roborock_local_client_v1] [Q5 Max+] Attempting to create a future with an existing id 2 (3)... New id is 39503. Code may not function properly.
2025-07-27 23:23:02.909 WARNING (MainThread) [roborock.version_1_apis.roborock_local_client_v1] [Q5 Max+] [Errno 104] Connection reset by peer
2025-07-27 23:23:04.763 ERROR (MainThread) [homeassistant.components.roborock.coordinator] Error fetching roborock data: Failed to update data
2025-07-27 23:23:24.650 WARNING (MainThread) [roborock.version_1_apis.roborock_local_client_v1] [Q5 Max+] Attempting to create a future with an existing id 2 (3)... New id is 39506. Code may not function properly.
2025-07-28 03:00:34.861 WARNING (MainThread) [roborock.version_1_apis.roborock_mqtt_client_v1] [Q5 Max+] Attempting to create a future with an existing id 1 (0)... New id is 42550. Code may not function properly.
2025-07-28 03:00:34.865 ERROR (MainThread) [homeassistant] Error doing job: Exception in callback RoborockFuture._set_result() (None)
Traceback (most recent call last):
  File "/usr/local/lib/python3.13/asyncio/events.py", line 89, in _run
    self._context.run(self._callback, *self._args)
    ~~~~~~~~~~~~~~~~~^^^^^^^^^^^^^^^^^^^^^^^^^^^^^
  File "/usr/local/lib/python3.13/site-packages/roborock/roborock_future.py", line 19, in _set_result
    self.fut.set_result(item)
    ~~~~~~~~~~~~~~~~~~~^^^^^^
asyncio.exceptions.InvalidStateError: invalid state
2025-07-28 06:45:10.973 WARNING (MainThread) [homeassistant.components.websocket_api.http.connection] [546972913472] from 192.168.8.154 (Mozilla/5.0 (Linux; Android 16; Pixel 7 Pro Build/BP2A.250705.008; wv) AppleWebKit/537.36 (KHTML, like Gecko) Version/4.0 Chrome/138.0.7204.158 Mobile Safari/537.36 Home Assistant/2025.7.1-16758 (Android 16; Pixel 7 Pro)): Disconnected: Did not receive auth message within 10 seconds
2025-07-28 06:46:11.736 WARNING (MainThread) [homeassistant.components.websocket_api.http.connection] [546972802784] from 192.168.8.154 (Mozilla/5.0 (Linux; Android 16; Pixel 7 Pro Build/BP2A.250705.008; wv) AppleWebKit/537.36 (KHTML, like Gecko) Version/4.0 Chrome/138.0.7204.158 Mobile Safari/537.36 Home Assistant/2025.7.1-16758 (Android 16; Pixel 7 Pro)): Disconnected: Received close message during auth phase
2025-07-28 11:00:21.849 WARNING (MainThread) [roborock.version_1_apis.roborock_mqtt_client_v1] [Q5 Max+] Attempting to create a future with an existing id 1 (0)... New id is 16911. Code may not function properly.
2025-07-28 11:00:21.852 ERROR (MainThread) [homeassistant] Error doing job: Exception in callback RoborockFuture._set_result() (None)
Traceback (most recent call last):
  File "/usr/local/lib/python3.13/asyncio/events.py", line 89, in _run
    self._context.run(self._callback, *self._args)
    ~~~~~~~~~~~~~~~~~^^^^^^^^^^^^^^^^^^^^^^^^^^^^^
  File "/usr/local/lib/python3.13/site-packages/roborock/roborock_future.py", line 19, in _set_result
    self.fut.set_result(item)
    ~~~~~~~~~~~~~~~~~~~^^^^^^
asyncio.exceptions.InvalidStateError: invalid state
2025-07-28 19:00:40.870 WARNING (MainThread) [roborock.version_1_apis.roborock_mqtt_client_v1] [Q5 Max+] Attempting to create a future with an existing id 1 (0)... New id is 23681. Code may not function properly.
2025-07-28 19:00:40.875 ERROR (MainThread) [homeassistant] Error doing job: Exception in callback RoborockFuture._set_result() (None)
Traceback (most recent call last):
  File "/usr/local/lib/python3.13/asyncio/events.py", line 89, in _run
    self._context.run(self._callback, *self._args)
    ~~~~~~~~~~~~~~~~~^^^^^^^^^^^^^^^^^^^^^^^^^^^^^
  File "/usr/local/lib/python3.13/site-packages/roborock/roborock_future.py", line 19, in _set_result
    self.fut.set_result(item)
    ~~~~~~~~~~~~~~~~~~~^^^^^^
asyncio.exceptions.InvalidStateError: invalid state
2025-07-28 22:28:19.464 WARNING (MainThread) [homeassistant.helpers.service] Referenced entities light.plug_in_lamp_dimming_module_8 are missing or not currently available
2025-07-28 22:28:19.465 WARNING (MainThread) [homeassistant.helpers.service] Referenced entities switch.plant_lights are missing or not currently available
2025-07-29 03:08:42.087 ERROR (MainThread) [homeassistant.components.roborock.coordinator] Error fetching roborock data: Failed to update data
2025-07-29 06:54:55.253 ERROR (MainThread) [frontend.js.modern.202507023] Uncaught error from Chrome WebView 138.0.7204.168 on Android 16
Script error.
null
@:0:0
2025-07-30 03:08:11.766 ERROR (MainThread) [homeassistant.components.roborock.coordinator] Error fetching roborock data: Failed to update data
2025-07-30 06:31:01.968 WARNING (MainThread) [homeassistant.components.websocket_api.http.connection] [547046311392] from 192.168.8.154 (Mozilla/5.0 (Linux; Android 16; Pixel 7 Pro Build/BP2A.250705.008; wv) AppleWebKit/537.36 (KHTML, like Gecko) Version/4.0 Chrome/138.0.7204.168 Mobile Safari/537.36 Home Assistant/2025.7.1-16758 (Android 16; Pixel 7 Pro)): Disconnected: Did not receive auth message within 10 seconds
2025-07-30 06:31:13.157 WARNING (MainThread) [homeassistant.components.websocket_api.http.connection] [546972797504] from 192.168.8.154 (Mozilla/5.0 (Linux; Android 16; Pixel 7 Pro Build/BP2A.250705.008; wv) AppleWebKit/537.36 (KHTML, like Gecko) Version/4.0 Chrome/138.0.7204.168 Mobile Safari/537.36 Home Assistant/2025.7.1-16758 (Android 16; Pixel 7 Pro)): Disconnected: Did not receive auth message within 10 seconds
2025-07-30 06:31:26.316 WARNING (MainThread) [homeassistant.components.websocket_api.http.connection] [546972803104] from 192.168.8.154 (Mozilla/5.0 (Linux; Android 16; Pixel 7 Pro Build/BP2A.250705.008; wv) AppleWebKit/537.36 (KHTML, like Gecko) Version/4.0 Chrome/138.0.7204.168 Mobile Safari/537.36 Home Assistant/2025.7.1-16758 (Android 16; Pixel 7 Pro)): Disconnected: Did not receive auth message within 10 seconds
2025-07-30 06:31:40.354 WARNING (MainThread) [homeassistant.components.websocket_api.http.connection] [547202429504] from 192.168.8.154 (Mozilla/5.0 (Linux; Android 16; Pixel 7 Pro Build/BP2A.250705.008; wv) AppleWebKit/537.36 (KHTML, like Gecko) Version/4.0 Chrome/138.0.7204.168 Mobile Safari/537.36 Home Assistant/2025.7.1-16758 (Android 16; Pixel 7 Pro)): Disconnected: Did not receive auth message within 10 seconds
2025-07-30 06:31:55.304 WARNING (MainThread) [homeassistant.components.websocket_api.http.connection] [547202424064] from 192.168.8.154 (Mozilla/5.0 (Linux; Android 16; Pixel 7 Pro Build/BP2A.250705.008; wv) AppleWebKit/537.36 (KHTML, like Gecko) Version/4.0 Chrome/138.0.7204.168 Mobile Safari/537.36 Home Assistant/2025.7.1-16758 (Android 16; Pixel 7 Pro)): Disconnected: Did not receive auth message within 10 seconds
2025-07-30 06:32:11.278 WARNING (MainThread) [homeassistant.components.websocket_api.http.connection] [547656111008] from 192.168.8.154 (Mozilla/5.0 (Linux; Android 16; Pixel 7 Pro Build/BP2A.250705.008; wv) AppleWebKit/537.36 (KHTML, like Gecko) Version/4.0 Chrome/138.0.7204.168 Mobile Safari/537.36 Home Assistant/2025.7.1-16758 (Android 16; Pixel 7 Pro)): Disconnected: Did not receive auth message within 10 seconds
2025-07-30 06:32:27.295 WARNING (MainThread) [homeassistant.components.websocket_api.http.connection] [547202424064] from 192.168.8.154 (Mozilla/5.0 (Linux; Android 16; Pixel 7 Pro Build/BP2A.250705.008; wv) AppleWebKit/537.36 (KHTML, like Gecko) Version/4.0 Chrome/138.0.7204.168 Mobile Safari/537.36 Home Assistant/2025.7.1-16758 (Android 16; Pixel 7 Pro)): Disconnected: Did not receive auth message within 10 seconds
2025-07-30 06:32:43.271 WARNING (MainThread) [homeassistant.components.websocket_api.http.connection] [547656111008] from 192.168.8.154 (Mozilla/5.0 (Linux; Android 16; Pixel 7 Pro Build/BP2A.250705.008; wv) AppleWebKit/537.36 (KHTML, like Gecko) Version/4.0 Chrome/138.0.7204.168 Mobile Safari/537.36 Home Assistant/2025.7.1-16758 (Android 16; Pixel 7 Pro)): Disconnected: Did not receive auth message within 10 seconds
2025-07-30 06:32:59.245 WARNING (MainThread) [homeassistant.components.websocket_api.http.connection] [547202517248] from 192.168.8.154 (Mozilla/5.0 (Linux; Android 16; Pixel 7 Pro Build/BP2A.250705.008; wv) AppleWebKit/537.36 (KHTML, like Gecko) Version/4.0 Chrome/138.0.7204.168 Mobile Safari/537.36 Home Assistant/2025.7.1-16758 (Android 16; Pixel 7 Pro)): Disconnected: Did not receive auth message within 10 seconds
2025-07-30 06:33:15.218 WARNING (MainThread) [homeassistant.components.websocket_api.http.connection] [547202515328] from 192.168.8.154 (Mozilla/5.0 (Linux; Android 16; Pixel 7 Pro Build/BP2A.250705.008; wv) AppleWebKit/537.36 (KHTML, like Gecko) Version/4.0 Chrome/138.0.7204.168 Mobile Safari/537.36 Home Assistant/2025.7.1-16758 (Android 16; Pixel 7 Pro)): Disconnected: Did not receive auth message within 10 seconds
2025-07-30 06:33:31.193 WARNING (MainThread) [homeassistant.components.websocket_api.http.connection] [547202515328] from 192.168.8.154 (Mozilla/5.0 (Linux; Android 16; Pixel 7 Pro Build/BP2A.250705.008; wv) AppleWebKit/537.36 (KHTML, like Gecko) Version/4.0 Chrome/138.0.7204.168 Mobile Safari/537.36 Home Assistant/2025.7.1-16758 (Android 16; Pixel 7 Pro)): Disconnected: Did not receive auth message within 10 seconds
2025-07-30 06:33:47.329 WARNING (MainThread) [homeassistant.components.websocket_api.http.connection] [547202521088] from 192.168.8.154 (Mozilla/5.0 (Linux; Android 16; Pixel 7 Pro Build/BP2A.250705.008; wv) AppleWebKit/537.36 (KHTML, like Gecko) Version/4.0 Chrome/138.0.7204.168 Mobile Safari/537.36 Home Assistant/2025.7.1-16758 (Android 16; Pixel 7 Pro)): Disconnected: Did not receive auth message within 10 seconds
2025-07-30 06:34:03.244 WARNING (MainThread) [homeassistant.components.websocket_api.http.connection] [547202521088] from 192.168.8.154 (Mozilla/5.0 (Linux; Android 16; Pixel 7 Pro Build/BP2A.250705.008; wv) AppleWebKit/537.36 (KHTML, like Gecko) Version/4.0 Chrome/138.0.7204.168 Mobile Safari/537.36 Home Assistant/2025.7.1-16758 (Android 16; Pixel 7 Pro)): Disconnected: Did not receive auth message within 10 seconds
2025-07-30 06:34:19.220 WARNING (MainThread) [homeassistant.components.websocket_api.http.connection] [546972797504] from 192.168.8.154 (Mozilla/5.0 (Linux; Android 16; Pixel 7 Pro Build/BP2A.250705.008; wv) AppleWebKit/537.36 (KHTML, like Gecko) Version/4.0 Chrome/138.0.7204.168 Mobile Safari/537.36 Home Assistant/2025.7.1-16758 (Android 16; Pixel 7 Pro)): Disconnected: Did not receive auth message within 10 seconds
2025-07-30 06:34:35.356 WARNING (MainThread) [homeassistant.components.websocket_api.http.connection] [546972797504] from 192.168.8.154 (Mozilla/5.0 (Linux; Android 16; Pixel 7 Pro Build/BP2A.250705.008; wv) AppleWebKit/537.36 (KHTML, like Gecko) Version/4.0 Chrome/138.0.7204.168 Mobile Safari/537.36 Home Assistant/2025.7.1-16758 (Android 16; Pixel 7 Pro)): Disconnected: Did not receive auth message within 10 seconds
2025-07-30 06:34:51.268 WARNING (MainThread) [homeassistant.components.websocket_api.http.connection] [547239790208] from 192.168.8.154 (Mozilla/5.0 (Linux; Android 16; Pixel 7 Pro Build/BP2A.250705.008; wv) AppleWebKit/537.36 (KHTML, like Gecko) Version/4.0 Chrome/138.0.7204.168 Mobile Safari/537.36 Home Assistant/2025.7.1-16758 (Android 16; Pixel 7 Pro)): Disconnected: Did not receive auth message within 10 seconds
2025-07-30 06:35:07.245 WARNING (MainThread) [homeassistant.components.websocket_api.http.connection] [546972804544] from 192.168.8.154 (Mozilla/5.0 (Linux; Android 16; Pixel 7 Pro Build/BP2A.250705.008; wv) AppleWebKit/537.36 (KHTML, like Gecko) Version/4.0 Chrome/138.0.7204.168 Mobile Safari/537.36 Home Assistant/2025.7.1-16758 (Android 16; Pixel 7 Pro)): Disconnected: Did not receive auth message within 10 seconds
2025-07-30 06:35:16.966 WARNING (MainThread) [homeassistant.components.websocket_api.http.connection] [547202423424] from 192.168.8.154 (Mozilla/5.0 (Linux; Android 16; Pixel 7 Pro Build/BP2A.250705.008; wv) AppleWebKit/537.36 (KHTML, like Gecko) Version/4.0 Chrome/138.0.7204.168 Mobile Safari/537.36 Home Assistant/2025.7.1-16758 (Android 16; Pixel 7 Pro)): Disconnected: Received close message during auth phase
2025-07-30 11:00:17.859 WARNING (MainThread) [roborock.version_1_apis.roborock_mqtt_client_v1] [Q5 Max+] Attempting to create a future with an existing id 1 (0)... New id is 20828. Code may not function properly.
2025-07-30 11:00:17.864 ERROR (MainThread) [homeassistant] Error doing job: Exception in callback RoborockFuture._set_result() (None)
Traceback (most recent call last):
  File "/usr/local/lib/python3.13/asyncio/events.py", line 89, in _run
    self._context.run(self._callback, *self._args)
    ~~~~~~~~~~~~~~~~~^^^^^^^^^^^^^^^^^^^^^^^^^^^^^
  File "/usr/local/lib/python3.13/site-packages/roborock/roborock_future.py", line 19, in _set_result
    self.fut.set_result(item)
    ~~~~~~~~~~~~~~~~~~~^^^^^^
asyncio.exceptions.InvalidStateError: invalid state
2025-07-30 17:30:15.761 ERROR (MainThread) [homeassistant.components.roborock.coordinator] Error fetching roborock data: Failed to update data
2025-07-30 17:31:15.868 WARNING (MainThread) [roborock.version_1_apis.roborock_local_client_v1] [Q5 Max+] Attempting to create a future with an existing id 2 (3)... New id is 26349. Code may not function properly.
2025-07-30 17:31:15.920 ERROR (MainThread) [homeassistant] Error doing job: Exception in callback RoborockFuture._set_result() (None)
Traceback (most recent call last):
  File "/usr/local/lib/python3.13/asyncio/events.py", line 89, in _run
    self._context.run(self._callback, *self._args)
    ~~~~~~~~~~~~~~~~~^^^^^^^^^^^^^^^^^^^^^^^^^^^^^
  File "/usr/local/lib/python3.13/site-packages/roborock/roborock_future.py", line 19, in _set_result
    self.fut.set_result(item)
    ~~~~~~~~~~~~~~~~~~~^^^^^^
asyncio.exceptions.InvalidStateError: invalid state
2025-07-30 18:32:56.761 ERROR (MainThread) [homeassistant.components.roborock.coordinator] Error fetching roborock data: Failed to update data
2025-07-30 18:32:57.468 WARNING (MainThread) [roborock.version_1_apis.roborock_local_client_v1] [Q5 Max+] Attempting to create a future with an existing id 2 (3)... New id is 27210. Code may not function properly.
2025-07-30 18:32:57.758 ERROR (MainThread) [homeassistant] Error doing job: Exception in callback RoborockFuture._set_result() (None)
Traceback (most recent call last):
  File "/usr/local/lib/python3.13/asyncio/events.py", line 89, in _run
    self._context.run(self._callback, *self._args)
    ~~~~~~~~~~~~~~~~~^^^^^^^^^^^^^^^^^^^^^^^^^^^^^
  File "/usr/local/lib/python3.13/site-packages/roborock/roborock_future.py", line 19, in _set_result
    self.fut.set_result(item)
    ~~~~~~~~~~~~~~~~~~~^^^^^^
asyncio.exceptions.InvalidStateError: invalid state
2025-07-30 19:00:26.838 WARNING (MainThread) [roborock.version_1_apis.roborock_mqtt_client_v1] [Q5 Max+] Attempting to create a future with an existing id 1 (0)... New id is 27597. Code may not function properly.
2025-07-30 19:00:26.842 ERROR (MainThread) [homeassistant] Error doing job: Exception in callback RoborockFuture._set_result() (None)
Traceback (most recent call last):
  File "/usr/local/lib/python3.13/asyncio/events.py", line 89, in _run
    self._context.run(self._callback, *self._args)
    ~~~~~~~~~~~~~~~~~^^^^^^^^^^^^^^^^^^^^^^^^^^^^^
  File "/usr/local/lib/python3.13/site-packages/roborock/roborock_future.py", line 19, in _set_result
    self.fut.set_result(item)
    ~~~~~~~~~~~~~~~~~~~^^^^^^
asyncio.exceptions.InvalidStateError: invalid state
2025-07-30 23:00:42.065 ERROR (MainThread) [dbus_fast.message_bus] "org.bluez.AdvertisementMonitor1.DeviceFound" with signature "o" could not be found
2025-07-31 03:00:21.839 WARNING (MainThread) [roborock.version_1_apis.roborock_mqtt_client_v1] [Q5 Max+] Attempting to create a future with an existing id 1 (0)... New id is 34465. Code may not function properly.
2025-07-31 03:00:21.842 ERROR (MainThread) [homeassistant] Error doing job: Exception in callback RoborockFuture._set_result() (None)
Traceback (most recent call last):
  File "/usr/local/lib/python3.13/asyncio/events.py", line 89, in _run
    self._context.run(self._callback, *self._args)
    ~~~~~~~~~~~~~~~~~^^^^^^^^^^^^^^^^^^^^^^^^^^^^^
  File "/usr/local/lib/python3.13/site-packages/roborock/roborock_future.py", line 19, in _set_result
    self.fut.set_result(item)
    ~~~~~~~~~~~~~~~~~~~^^^^^^
asyncio.exceptions.InvalidStateError: invalid state
2025-07-31 07:18:59.863 WARNING (MainThread) [roborock.version_1_apis.roborock_mqtt_client_v1] [Q5 Max+] Attempting to create a future with an existing id 1 (0)... New id is 38522. Code may not function properly.
2025-07-31 07:18:59.868 ERROR (MainThread) [homeassistant] Error doing job: Exception in callback RoborockFuture._set_result() (None)
Traceback (most recent call last):
  File "/usr/local/lib/python3.13/asyncio/events.py", line 89, in _run
    self._context.run(self._callback, *self._args)
    ~~~~~~~~~~~~~~~~~^^^^^^^^^^^^^^^^^^^^^^^^^^^^^
  File "/usr/local/lib/python3.13/site-packages/roborock/roborock_future.py", line 19, in _set_result
    self.fut.set_result(item)
    ~~~~~~~~~~~~~~~~~~~^^^^^^
asyncio.exceptions.InvalidStateError: invalid state
2025-07-31 07:37:37.940 WARNING (MainThread) [roborock.version_1_apis.roborock_local_client_v1] [Q5 Max+] Attempting to create a future with an existing id 2 (3)... New id is 38799. Code may not function properly.
2025-07-31 07:37:40.762 ERROR (MainThread) [homeassistant.components.roborock.coordinator] Error fetching roborock data: Failed to update data
2025-07-31 10:23:45.785 ERROR (MainThread) [dbus_fast.message_bus] "org.bluez.AdvertisementMonitor1.DeviceFound" with signature "o" could not be found
2025-07-31 21:15:55.701 ERROR (MainThread) [homeassistant.components.automation] Automation with alias 'Outdoor Lights On at Sunset' failed to setup actions and has been disabled: Unknown device 'cfb8cff49b4fc7c05f007793e10e2808'
2025-07-31 21:15:55.999 WARNING (MainThread) [roborock.version_1_apis.roborock_mqtt_client_v1] [Q5 Max+] Attempting to create a future with an existing id 1 (0)... New id is 17485. Code may not function properly.
2025-07-31 21:15:56.010 ERROR (MainThread) [homeassistant] Error doing job: Exception in callback RoborockFuture._set_result() (None)
Traceback (most recent call last):
  File "/usr/local/lib/python3.13/asyncio/events.py", line 89, in _run
    self._context.run(self._callback, *self._args)
    ~~~~~~~~~~~~~~~~~^^^^^^^^^^^^^^^^^^^^^^^^^^^^^
  File "/usr/local/lib/python3.13/site-packages/roborock/roborock_future.py", line 19, in _set_result
    self.fut.set_result(item)
    ~~~~~~~~~~~~~~~~~~~^^^^^^
asyncio.exceptions.InvalidStateError: invalid state
2025-07-31 21:16:06.011 ERROR (MainThread) [homeassistant] Error doing job: Task exception was never retrieved (None)
Traceback (most recent call last):
  File "/usr/src/homeassistant/homeassistant/components/roborock/__init__.py", line 126, in on_stop
    await asyncio.gather(
    ...<4 lines>...
    )
  File "/usr/src/homeassistant/homeassistant/components/roborock/coordinator.py", line 288, in async_shutdown
    await asyncio.gather(
    ...<3 lines>...
    )
  File "/usr/local/lib/python3.13/site-packages/roborock/version_1_apis/roborock_client_v1.py", line 169, in async_release
    await super().async_release()
  File "/usr/local/lib/python3.13/site-packages/roborock/api.py", line 51, in async_release
    await self.async_disconnect()
  File "/usr/local/lib/python3.13/site-packages/roborock/cloud_api.py", line 161, in async_disconnect
    await disconnected_future
  File "/usr/local/lib/python3.13/site-packages/roborock/api.py", line 99, in _wait_response
    raise RoborockTimeout(f"id={request_id} Timeout after {self.queue_timeout} seconds") from None
roborock.exceptions.RoborockTimeout: id=17485 Timeout after 10 seconds
